Workbook
Name column_headings: #REF!
Name column_headings: #REF!
Name column_headings: #REF!
Name column_headings: #REF!
Name column_headings: #REF!
Name column_headings: #REF!
Name column_headings: #REF!
Name column_headings: #REF!
Name column_headings: #REF!
Name column_numbers: #REF!
Name column_numbers: #REF!
Name column_numbers: #REF!
Name column_numbers: #REF!
Name column_numbers: #REF!
Name column_numbers: #REF!
Name column_numbers: #REF!
Name column_numbers: #REF!
Name column_numbers: #REF!
Name d: #REF!
Name d: #REF!
Name d: #REF!
Name d: #REF!
Name d: #REF!
Name d: #REF!
Name d: #REF!
Name d: #REF!
Name d: #REF!
Name data: #REF!
Name data: #REF!
Name data: #REF!
Name data: #REF!
Name data: #REF!
Name data: #REF!
Name data: #REF!
Name data: #REF!
Name data: #REF!
Name e: #REF!
Name e: #REF!
Name e: #REF!
Name e: #REF!
Name e: #REF!
Name e: #REF!
Name e: #REF!
Name e: #REF!
Name e: #REF!
Name ea_flux: #REF!
Name ea_flux: #REF!
Name ea_flux: #REF!
Name ea_flux: #REF!
Name ea_flux: #REF!
Name ea_flux: #REF!
Name ea_flux: #REF!
Name ea_flux: #REF!
Name ea_flux: #REF!
Name Equilibre: #REF!
Name Equilibre: #REF!
Name Equilibre: #REF!
Name Equilibre: #REF!
Name Equilibre: #REF!
Name Equilibre: #REF!

Sheet Table A0
B3: Main Tables
B4: Table | C4: A1 | D4: Global Cross-Border Securities Assets
B5: Table | C5: A2 | D5: Global Cross-Border Securities Liabilities
B6: Table | C6: A3 | D6: Global Discrepancy Between Cross-Border Securities Assets and Liabilities
C7: Securities Assets (Appendix Section A)
B8: Table | C8: A4 | D8: Main Holders of Cross-Border Securities
B9: Table | C9: A5 | D9: Sectoral Breakdown of Securities Claims Reported in the CPIS, year-end 2008
B10: Table | C10: A6 | D10: Cayman Islands' Cross-Border Securities Assets and Liabilities
B11: Table | C11: A7 | D11: China's Cross-Border Securities Assets
B12: Table | C12: A8 | D12: Middle-East Oil Exporting Countries' Cross-Border Securities Assets
B13: Table | C13: A9 | D13: Other non-CPIS Countries Cross-Border Securities Assets
B14: Table | C14: A9b | D14: Bilateral Portfoio Holdings, Panel Regressions
B15: Table | C15: A9c | D15: Bilateral Portfoio Holdings in and of Offshore Financial Centers, Panel Regressions
C16: Securities Liabilities (Appendix Section B)
B17: Table | C17: A10 | D17: Cross-Border Equity Liabilities of Small Offshore Financial Centers
B18: Table | C18: A11 | D18: Cross-Border Debt Liabilities of Small Offshore Financial Centers
B19: Table | C19: A12 | D19: Raw CPIS-derived liabilities > reported liabilities (bn of USD)
D20: Missing Securities (Appendix Section C)
B21: Table | C21: A13 | D21: Reported Equity Liabilities Minus Creditor-Derived Liabilities
B22: Table | C22: A14 | D22: Reported Debt Liabilities Minus Creditor-Derived Liabilities
B23: Table | C23: A15 | D23: Investment Patterns of Reserve Managers and International Organizations (SEFER-SSIO)
B24: Table | C24: A16 | D24: Recorded vs. Predicted Shares of Each Developed Country in the Global Portfolio of CPIS-Participating Countries
B25: Table | C25: A17 | D25: Recorded vs. predicted shares of each country in the U.S., Japanese, and French portfolios
B26: Table | C26: A18 | D26: Unindentified Investments in U.S. Equities
C27: Flow Data (Appendix Section D)
B28: Table | C28: A19 | D28: The World Current Account: Credits
B29: Table | C29: A20 | D29: The World Current Acount: Debits
B30: Table | C30: A21 | D30: The World Current Account: Discrepancies
B31: Table | C31: A22 | D31: Yield on Global Cross-Border Bank Deposits and Portfolio Claims
C32: Offshore Fortunes in Switzerland (Appendix Section E)
B33: Table | C33: A23 | D33: Securities in Custody in Swiss Banks
B34: Table | C34: A24 | D34: Fiduciary Deposits in Swiss Banks, 1976-2008
B35: Table | C35: A25 | D35: Distribution of Fiduciary Deposits in Swiss Banks by Country of Owner, Uncorrected Shares
B36: Table | C36: A26 | D36: Distribution of Fiduciary Deposits in Swiss Banks by Country of Owner, Corrected Shares
D37: Net Foreign Asset Positions (Appendix Section F)
B38: Table | C38: A27 | D38: Net Foreign Asset Positions of Rich Countries, As Officially Reported
B39: Table | C39: A28 | D39: Euro-Area Net Foreign Asset Position/Euro-Area GDP
B40: Table | C40: A29 | D40: U.S. Net Foreign Asset Position/U.S. GDP
B41: Table | C41: A30 | D41: Households' Unrecorded Offshore Assets vs. Net Debt of the World
B42: Table | C42: A31 | D42: Euro-Area Net Foreign Asset Position/Euro-Area GDP, World IIP balanced
...

Sheet Table A1
B2: Table A1: Global Cross-Border Securities Assets
C4: [1] | D4: [2] | E4: [3] | F4: [4] | G4: [5] | H4: [6] | I4: [7] | J4: [8] | K4: [9] | L4: [10] | M4: [11] | N4: [12] | O4: [13] | P4: [14] | Q4: [15] | R4: [16]
C5: Billions of current USD
C6: CPIS assets | D6: Of which: SEFER + SSIO | E6: Correction for CPIS reporting countries | G6: Correction for non-CPIS reporting countries | O6: Total securities assets | P6: Of which: reserves + int'l orga.
E7: Cayman Islands non-bank sector | F7: Other | G7: China | I7: Middle-East oil exporters (onshore) | L7: Other
H8: Of which: held as reserve | J8: Of which: held as reserve | K8: Of which: reported in CPIS | L8: Middle-East oil exporters onshore assets | M8: Of which: private portfolios | N8: Of which: reserve | Q8: Memo: (CPIS + SEFER) / Total assets | R8: Memo: reserve minus bank deposits
C9: Panel A: All securities
B11: 2001 | C11: =C21+C31 -> 12710.853 | D11: =D21+D31 -> 1281.8058 | E11: =E21+E31 -> 291.65509 | F11: =F21+F31 -> 36.468623 | G11: =G21+G31 -> 213.7776 | H11: =H21+H31 -> 180.34025 | I11: =I21+I31 -> 146.4572 | J11: {=0.75*TRANSPOSE('Table A8'!D24:K24)} -> 49.197753 | K11: =K21+K31 -> 21.680933 | L11: =L21+L31 -> 363.03952 | M11: =M21+M31 -> 174.01075 | N11: =N21+N31 -> 189.02877 | O11: =C11+E11+F11+G11+I11-K11+L11 -> 13740.57 | P11: =P21+P31 -> 1700.3726 | Q11: =C11/O11 -> 0.92506009 | R11: =(RawDataSources!AI41-RawDataSources!AM41)/1000 -> 1657.247
B12: =B11+1 -> 2002 | C12: =C22+C32 -> 14115.852 | D12: =D22+D32 -> 1429.1011 | E12: =E22+E32 -> 371.16791 | F12: =F22+F32 -> 46.760597 | G12: =G22+G32 -> 290.22395 | H12: =H22+H32 -> 243.44595 | I12: =I22+I32 -> 136.91837 | J12: 55.144694 | K12: =K22+K32 -> 21.372506 | L12: =L22+L32 -> 422.43993 | M12: =M22+M32 -> 192.039 | N12: =N22+N32 -> 230.40093 | O12: =C12+E12+F12+G12+I12-K12+L12 -> 15361.99 | P12: =P22+P32 -> 1958.0927 | Q12: =C12/O12 -> 0.91888172 | R12: =(RawDataSources!AI42-RawDataSources!AM42)/1000 -> 1986.048
B13: =B12+1 -> 2003 | C13: =C23+C33 -> 19046.516 | D13: =D23+D33 -> 1849.7833 | E13: =E23+E33 -> 555.8249 | F13: =F23+F33 -> 59.053496 | G13: =G23+G33 -> 407.24592 | H13: =H23+H33 -> 342.76335 | I13: =I23+I33 -> 166.65121 | J13: 58.258316 | K13: =K23+K33 -> 28.836573 | L13: =L23+L33 -> 573.39657 | M13: =M23+M33 -> 281.51793 | N13: =N23+N33 -> 291.87863 | O13: =C13+E13+F13+G13+I13-K13+L13 -> 20779.851 | P13: =P23+P33 -> 2542.6836 | Q13: =C13/O13 -> 0.91658576 | R13: =(RawDataSources!AI43-RawDataSources!AM43)/1000 -> 2442.239
B14: =B13+1 -> 2004 | C14: =C24+C34 -> 23268.837 | D14: =D24+D34 -> 2145.013 | E14: =E24+E34 -> 799.76576 | F14: =F24+F34 -> 46.932239 | G14: =G24+G34 -> 611.26998 | H14: =H24+H34 -> 518.4422 | I14: =I24+I34 -> 247.71803 | J14: 77.82074 | K14: =K24+K34 -> 35.311256 | L14: =L24+L34 -> 694.88537 | M14: =M24+M34 -> 340.07844 | N14: =N24+N34 -> 354.80693 | O14: =C14+E14+F14+G14+I14-K14+L14 -> 25634.097 | P14: =P24+P34 -> 3096.0829 | Q14: =C14/O14 -> 0.90772992 | R14: =(RawDataSources!AI44-RawDataSources!AM44)/1000 -> 2985.902
B15: =B14+1 -> 2005 | C15: =C25+C35 -> 25892.148 | D15: =D25+D35 -> 2221.1363 | E15: =E25+E35 -> 839.10843 | F15: =F25+F35 -> 64.922443 | G15: =G25+G35 -> 813.72616 | H15: =H25+H35 -> 696.0412 | I15: =I25+I35 -> 309.96829 | J15: 96.484877 | K15: =K25+K35 -> 45.820693 | L15: =L25+L35 -> 848.94141 | M15: =M25+M35 -> 444.21981 | N15: =N25+N35 -> 404.7216 | O15: =C15+E15+F15+G15+I15-K15+L15 -> 28722.994 | P15: =P25+P35 -> 3418.384 | Q15: =C15/O15 -> 0.90144321 | R15: =(RawDataSources!AI45-RawDataSources!AM45)/1000 -> 3371.147
B16: =B15+1 -> 2006 | C16: =C26+C36 -> 32964.246 | D16: =D26+D36 -> 2558.3584 | E16: =E26+E36 -> 1252.293 | F16: =F26+F36 -> 57.730729 | G16: =G26+G36 -> 1174.2003 | H16: =H26+H36 -> 906.389 | I16: =I26+I36 -> 431.42602 | J16: 123.54326 | K16: =K26+K36 -> 62.728798 | L16: =L26+L36 -> 1154.4216 | M16: =M26+M36 -> 659.75461 | N16: =N26+N36 -> 494.66695 | O16: =C16+E16+F16+G16+I16-K16+L16 -> 36971.589 | P16: =P26+P36 -> 4082.9576 | Q16: =C16/O16 -> 0.89161021 | R16: =(RawDataSources!AI46-RawDataSources!AM46)/1000 -> 4068.289
B17: =B16+1 -> 2007 | C17: =C27+C37 -> 39064.507 | D17: =D27+D37 -> 3109.3694 | E17: =E27+E37 -> 1543.7509 | F17: =F27+F37 -> 91.012539 | G17: =G27+G37 -> 1584.8535 | H17: =H27+H37 -> 1299.0125 | I17: =I27+I37 -> 590.4653 | J17: 201.45624 | K17: =K27+K37 -> 79.214444 | L17: =L27+L37 -> 1374.7419 | M17: =M27+M37 -> 789.8375 | N17: =N27+N37 -> 584.90439 | O17: =C17+E17+F17+G17+I17-K17+L17 -> 44170.116 | P17: =P27+P37 -> 5194.7425 | Q17: =C17/O17 -> 0.88441032 | R17: =(RawDataSources!AI47-RawDataSources!AM47)/1000 -> 5257.231
B18: =B17+1 -> 2008 | C18: =C28+C38 -> 30717.961 | D18: =D28+D38 -> 3643.0773 | E18: =E28+E38 -> 1202.651 | F18: =F28+F38 -> 84.203377 | G18: =G28+G38 -> 1906.0057 | H18: =H28+H38 -> 1654.1255 | I18: =I28+I38 -> 587.02789 | J18: 180.19177 | K18: =K28+K38 -> 73.597697 | L18: =L28+L38 -> 1183.0504 | M18: =M28+M38 -> 536.0478 | N18: =N28+N38 -> 647.00258 | O18: =C18+E18+F18+G18+I18-K18+L18 -> 35607.301 | P18: =P28+P38 -> 6124.3972 | Q18: =C18/O18 -> 0.86268713 | R18: =(RawDataSources!AI48-RawDataSources!AM48)/1000 -> 6196.806
C19: Panel B: Equities
B21: 2001 | C21: =RawDataSources!B41/1000 -> 5200.1451 | D21: =RawDataSources!C41/1000 -> 17.159837 | E21: {=TRANSPOSE('Table A6'!D15:K15)-TRANSPOSE('Table A6'!D20:K20)} -> 163.95461 | F21: =(RawDataSources!M41+RawDataSources!O41)/1000 -> 7.3843888 | G21: {=TRANSPOSE('Table A7'!D25:K25)} -> 5.4734656 | H21: {=TRANSPOSE('Table A7'!D9:K9)} -> 4.3428278 | I21: {=TRANSPOSE('Table A8'!D23:K23)} -> 64.55 | J21: =J11*I21/I11 -> 21.683569 | K21: {=TRANSPOSE('Table A8'!$D$11:$K$11)} -> 6.3482286 | L21: =M21+N21 -> 118.5172 | M21: {=TRANSPOSE('Table A9'!D12:K12)} -> 115.99681 | N21: {=TRANSPOSE('Table A9'!D8:K8)} -> 2.5203835 | O21: =C21+E21+F21+G21+I21-K21+L21 -> 5553.6765 | P21: =D21+J21+H21+N21 -> 45.706618 | Q21: =C21/O21 -> 0.93634281
B22: =B21+1 -> 2002 | C22: =RawDataSources!B42/1000 -> 4796.3675 | D22: =RawDataSources!C42/1000 -> 14.372878 | E22: 197.16352 | F22: =(RawDataSources!M42+RawDataSources!O42)/1000 -> 8.8240881 | G22: 3.6354878 | H22: 2.8582829 | I22: 55.686765 | J22: =J12*I22/I12 -> 22.428178 | K22: 5.3800367 | L22: =M22+N22 -> 117.5484 | M22: 114.47639 | N22: 3.0720125 | O22: =C22+E22+F22+G22+I22-K22+L22 -> 5173.8457 | P22: =D22+J22+H22+N22 -> 42.731351 | Q22: =C22/O22 -> 0.92704107
B23: =B22+1 -> 2003 | C23: =RawDataSources!B43/1000 -> 6949.9986 | D23: =RawDataSources!C43/1000 -> 26.814457 | E23: 334.21691 | F23: =(RawDataSources!M43+RawDataSources!O43)/1000 -> 8.8998678 | G23: 3.3292932 | H23: 2.6290851 | I23: 87.266667 | J23: =J13*I23/I13 -> 30.506884 | K23: 7.7957429 | L23: =M23+N23 -> 170.1795 | M23: 166.28779 | N23: 3.8917147 | O23: =C23+E23+F23+G23+I23-K23+L23 -> 7546.0951 | P23: =D23+J23+H23+N23 -> 63.842141 | Q23: =C23/O23 -> 0.92100596
B24: =B23+1 -> 2004 | C24: =RawDataSources!B44/1000 -> 8705.2589 | D24: =RawDataSources!C44/1000 -> 35.078451 | E24: 401.83489 | F24: =(RawDataSources!M44+RawDataSources!O44)/1000 -> 3.8484327 | G24: 3.9627292 | H24: 3.1629463 | I24: 123.13594 | J24: =J14*I24/I14 -> 38.683214 | K24: 10.738219 | L24: =M24+N24 -> 198.25691 | M24: 193.52615 | N24: 4.7307592 | O24: =C24+E24+F24+G24+I24-K24+L24 -> 9425.5596 | P24: =D24+J24+H24+N24 -> 81.65537 | Q24: =C24/O24 -> 0.92358006
B25: =B24+1 -> 2005 | C25: =RawDataSources!B45/1000 -> 10586.279 | D25: =RawDataSources!C45/1000 -> 35.494522 | E25: 430.09094 | F25: =(RawDataSources!M45+RawDataSources!O45)/1000 -> 4.9295695 | G25: 4.3742458 | H25: 3.4282846 | I25: 153.02258 | J25: =J15*I25/I15 -> 47.631856 | K25: 15.751527 | L25: =M25+N25 -> 258.10074 | M25: 252.70445 | N25: 5.3962885 | O25: =C25+E25+F25+G25+I25-K25+L25 -> 11421.045 | P25: =D25+J25+H25+N25 -> 91.950951 | Q25: =C25/O25 -> 0.9269098
B26: =B25+1 -> 2006 | C26: =RawDataSources!B46/1000 -> 14248.964 | D26: =RawDataSources!C46/1000 -> 43.167668 | E26: 616.033 | F26: =(RawDataSources!M46+RawDataSources!O46)/1000 -> 9.5943506 | G26: 20.392324 | H26: 16.305992 | I26: 213.165 | J26: =J16*I26/I16 -> 61.041982 | K26: 24.550534 | L26: =M26+N26 -> 427.50216 | M26: 420.9066 | N26: 6.595559 | O26: =C26+E26+F26+G26+I26-K26+L26 -> 15511.1 | P26: =D26+J26+H26+N26 -> 127.1112 | Q26: =C26/O26 -> 0.91863012
B27: =B26+1 -> 2007 | C27: =RawDataSources!B47/1000 -> 17094.158 | D27: =RawDataSources!C47/1000 -> 54.442976 | E27: 773.38608 | F27: =(RawDataSources!M47+RawDataSources!O47)/1000 -> 24.280806 | G27: 104.23623 | H27: 83.373269 | I27: 258.72931 | J27: =J17*I27/I17 -> 88.27383 | K27: 33.396631 | L27: =M27+N27 -> 516.96149 | M27: 509.16276 | N27: 7.7987255 | O27: =C27+E27+F27+G27+I27-K27+L27 -> 18738.356 | P27: =D27+J27+H27+N27 -> 233.8888 | Q27: =C27/O27 -> 0.91225499
B28: =B27+1 -> 2008 | C28: =RawDataSources!B48/1000 -> 9836.2771 | D28: =RawDataSources!C48/1000 -> 39.445316 | E28: 458.23029 | F28: =(RawDataSources!M48+RawDataSources!O48)/1000 -> 21.706335 | G28: 94.675627 | H28: 73.915427 | I28: 182.59107 | J28: =J18*I28/I18 -> 56.047438 | K28: 39.106084 | L28: =M28+N28 -> 291.82285 | M28: 283.19614 | N28: 8.6267009 | O28: =C28+E28+F28+G28+I28-K28+L28 -> 10846.197 | P28: =D28+J28+H28+N28 -> 178.03488 | Q28: =C28/O28 -> 0.90688717
C29: Panel C: Debt
B31: 2001 | C31: =RawDataSources!D41/1000 -> 7510.7083 | D31: =RawDataSources!E41/1000 -> 1264.646 | E31: {=TRANSPOSE('Table A6'!D16:K16)-TRANSPOSE('Table A6'!D21:K21)} -> 127.70048 | F31: =(RawDataSources!N41+RawDataSources!P41)/1000 -> 29.084234 | G31: {=TRANSPOSE('Table A7'!D26:K26)} -> 208.30413 | H31: {=TRANSPOSE('Table A7'!D10:K10)} -> 175.99742 | I31: {=TRANSPOSE('Table A8'!D22:K22)-TRANSPOSE('Table A8'!D23:K23)} -> 81.907203 | J31: =J11*I31/I11 -> 27.514183 | K31: {=TRANSPOSE('Table A8'!$D$10:$K$10)-TRANSPOSE('Table A8'!$D$11:$K$11)} -> 15.332704 | L31: =M31+N31 -> 244.52232 | M31: {=TRANSPOSE('Table A9'!D13:K13)} -> 58.013934 | N31: {=TRANSPOSE('Table A9'!D9:K9)} -> 186.50839 | O31: =C31+E31+F31+G31+I31-K31+L31 -> 8186.8939 | P31: =D31+J31+H31+N31 -> 1654.6659 | Q31: =C31/O31 -> 0.91740632
B32: =B31+1 -> 2002 | C32: =RawDataSources!D42/1000 -> 9319.4843 | D32: =RawDataSources!E42/1000 -> 1414.7282 | E32: 174.00439 | F32: =(RawDataSources!N42+RawDataSources!P42)/1000 -> 37.936509 | G32: 286.58846 | H32: 240.58767 | I32: 81.23161 | J32: =J12*I32/I12 -> 32.716517 | K32: 15.992469 | L32: =M32+N32 -> 304.89153 | M32: 77.562613 | N32: 227.32892 | O32: =C32+E32+F32+G32+I32-K32+L32 -> 10188.144 | P32: =D32+J32+H32+N32 -> 1915.3613 | Q32: =C32/O32 -> 0.91473815
B33: =B32+1 -> 2003 | C33: =RawDataSources!D43/1000 -> 12096.517 | D33: =RawDataSources!E43/1000 -> 1822.9688 | E33: 221.60799 | F33: =(RawDataSources!N43+RawDataSources!P43)/1000 -> 50.153628 | G33: 403.91662 | H33: 340.13426 | I33: 79.384542 | J33: =J13*I33/I13 -> 27.751432 | K33: 21.04083 | L33: =M33+N33 -> 403.21707 | M33: 115.23015 | N33: 287.98692 | O33: =C33+E33+F33+G33+I33-K33+L33 -> 13233.756 | P33: =D33+J33+H33+N33 -> 2478.8414 | Q33: =C33/O33 -> 0.91406529
B34: =B33+1 -> 2004 | C34: =RawDataSources!D44/1000 -> 14563.578 | D34: =RawDataSources!E44/1000 -> 2109.9345 | E34: 397.93087 | F34: =(RawDataSources!N44+RawDataSources!P44)/1000 -> 43.083806 | G34: 607.30725 | H34: 515.27925 | I34: 124.5821 | J34: =J14*I34/I14 -> 39.137526 | K34: 24.573037 | L34: =M34+N34 -> 496.62846 | M34: 146.55229 | N34: 350.07617 | O34: =C34+E34+F34+G34+I34-K34+L34 -> 16208.538 | P34: =D34+J34+H34+N34 -> 3014.4275 | Q34: =C34/O34 -> 0.89851278
B35: =B34+1 -> 2005 | C35: =RawDataSources!D45/1000 -> 15305.869 | D35: =RawDataSources!E45/1000 -> 2185.6418 | E35: 409.01749 | F35: =(RawDataSources!N45+RawDataSources!P45)/1000 -> 59.992874 | G35: 809.35192 | H35: 692.61292 | I35: 156.94571 | J35: =J15*I35/I15 -> 48.853021 | K35: 30.069166 | L35: =M35+N35 -> 590.84067 | M35: 191.51536 | N35: 399.32531 | O35: =C35+E35+F35+G35+I35-K35+L35 -> 17301.949 | P35: =D35+J35+H35+N35 -> 3326.433 | Q35: =C35/O35 -> 0.88463268
B36: =B35+1 -> 2006 | C36: =RawDataSources!D46/1000 -> 18715.283 | D36: =RawDataSources!E46/1000 -> 2515.1907 | E36: 636.25997 | F36: =(RawDataSources!N46+RawDataSources!P46)/1000 -> 48.136378 | G36: 1153.808 | H36: 890.08301 | I36: 218.26102 | J36: =J16*I36/I16 -> 62.50128 | K36: 38.178264 | L36: =M36+N36 -> 726.9194 | M36: 238.84801 | N36: 488.07139 | O36: =C36+E36+F36+G36+I36-K36+L36 -> 21460.489 | P36: =D36+J36+H36+N36 -> 3955.8464 | Q36: =C36/O36 -> 0.8720809
B37: =B36+1 -> 2007 | C37: =RawDataSources!D47/1000 -> 21970.348 | D37: =RawDataSources!E47/1000 -> 3054.9264 | E37: 770.36478 | F37: =(RawDataSources!N47+RawDataSources!P47)/1000 -> 66.731733 | G37: 1480.6172 | H37: 1215.6392 | I37: 331.73599 | J37: =J17*I37/I17 -> 113.18241 | K37: 45.817813 | L37: =M37+N37 -> 857.7804 | M37: 280.67474 | N37: 577.10567 | O37: =C37+E37+F37+G37+I37-K37+L37 -> 25431.761 | P37: =D37+J37+H37+N37 -> 4960.8537 | Q37: =C37/O37 -> 0.86389411
B38: =B37+1 -> 2008 | C38: =RawDataSources!D48/1000 -> 20881.684 | D38: =RawDataSources!E48/1000 -> 3603.632 | E38: 744.42071 | F38: =(RawDataSources!N48+RawDataSources!P48)/1000 -> 62.497043 | G38: 1811.3301 | H38: 1580.2101 | I38: 404.43681 | J38: =J18*I38/I18 -> 124.14434 | K38: 34.491614 | L38: =M38+N38 -> 891.22753 | M38: 252.85165 | N38: 638.37588 | O38: =C38+E38+F38+G38+I38-K38+L38 -> 24761.104 | P38: =D38+J38+H38+N38 -> 5946.3623 | Q38: =C38/O38 -> 0.84332603

Sheet Table A2
B2: Table A2: Global Cross-Border Securities Liabilities
C3: [1] | D3: [2] | E3: [3] | F3: [4] | G3: [5] | H3: [6] | I3: [7] | J3: [8] | K3: [9] | L3: [10] | M3: [11] | N3: [12] | O3: [13] | P3: [14]
C4: Billions of current USD
C5: EWNII liabilities | D5: Memo: IMF IIPs | E5: Correction to EWNII data | H5: Non EWNII countries | L5: int'l orga. | M5: Total securities liabilities | O5: Memo: Int'l debt securities (BIS)
E6: No debt data | F6: Netherlands SFIs | G6: raw CPIS derived liabilities > reported liabilities | H6: Small OFCs | K6: Other
H7: Cayman Islands | I7: Other small OFCs | J7: Memo: small OFCs / Total | N7: EWNII liabilities / Total liabilities | P7: Cross-border debt / International debt
C8: Panel A: All securities
B10: 2001 | C10: =C20+C30 -> 14055.461 | D10: =D20+D30 -> 13144.364 | E10: =E30 -> 35.256787 | F10: =F20+F30 -> 264.93128 | G10: =G20+G30 -> 242.30787 | H10: =H20+H30 -> 708.37453 | I10: =I20+I30 -> 563.06188 | J10: =(H10+I10)/M10 -> 0.078133857 | K10: =K20+K30 -> 17.041344 | L10: =L20+L30 -> 386.10616 | M10: =C10+E10+F10+G10+H10+I10+K10+L10 -> 16272.541 | N10: =C10/M10 -> 0.86375331
B11: =B10+1 -> 2002 | C11: =C21+C31 -> 15332.219 | D11: =D21+D31 -> 15232.939 | E11: =E31 -> 30.771808 | F11: =F21+F31 -> 326.48418 | G11: =G21+G31 -> 198.41887 | H11: =H21+H31 -> 838.10853 | I11: =I21+I31 -> 565.13942 | J11: =(H11+I11)/M11 -> 0.079038394 | K11: =K21+K31 -> 17.352415 | L11: =L21+L31 -> 445.51023 | M11: =C11+E11+F11+G11+H11+I11+K11+L11 -> 17754.004 | N11: =C11/M11 -> 0.86359215
B12: =B11+1 -> 2003 | C12: =C22+C32 -> 20482.742 | D12: =D22+D32 -> 20256.346 | E12: =E32 -> 47.144951 | F12: =F22+F32 -> 435.16014 | G12: =G22+G32 -> 268.61156 | H12: =H22+H32 -> 1090.2475 | I12: =I22+I32 -> 780.2814 | J12: =(H12+I12)/M12 -> 0.079133846 | K12: =K22+K32 -> 19.191915 | L12: =L22+L32 -> 514.15353 | M12: =C12+E12+F12+G12+H12+I12+K12+L12 -> 23637.533 | N12: =C12/M12 -> 0.86653468
B13: =B12+1 -> 2004 | C13: =C23+C33 -> 25199.734 | D13: =D23+D33 -> 24956.823 | E13: =E33 -> 57.73496 | F13: =F23+F33 -> 458.45184 | G13: =G23+G33 -> 225.1329 | H13: =H23+H33 -> 1456.704 | I13: =I23+I33 -> 952.71686 | J13: =(H13+I13)/M13 -> 0.083226619 | K13: =K23+K33 -> 30.311703 | L13: =L23+L33 -> 569.33627 | M13: =C13+E13+F13+G13+H13+I13+K13+L13 -> 28950.123 | N13: =C13/M13 -> 0.87045345
B14: =B13+1 -> 2005 | C14: =C24+C34 -> 28162.658 | D14: =D24+D34 -> 27763.891 | E14: =E34 -> 74.650013 | F14: =F24+F34 -> 393.80634 | G14: =G24+G34 -> 456.19876 | H14: =H24+H34 -> 1591.9923 | I14: =I24+I34 -> 1119.2626 | J14: =(H14+I14)/M14 -> 0.083684243 | K14: =K24+K34 -> 40.871859 | L14: =L24+L34 -> 559.19179 | M14: =C14+E14+F14+G14+H14+I14+K14+L14 -> 32398.632 | N14: =C14/M14 -> 0.86925455
B15: =B14+1 -> 2006 | C15: =C25+C35 -> 35459.048 | D15: =D25+D35 -> 34691.749 | E15: =E35 -> 103.84103 | F15: =F25+F35 -> 515.67033 | G15: =G25+G35 -> 429.84205 | H15: =H25+H35 -> 2141.7476 | I15: =I25+I35 -> 1430.8112 | J15: =(H15+I15)/M15 -> 0.087709777 | K15: =K25+K35 -> 51.59445 | L15: =L25+L35 -> 599.03793 | M15: =C15+E15+F15+G15+H15+I15+K15+L15 -> 40731.592 | N15: =C15/M15 -> 0.87055393
B16: =B15+1 -> 2007 | C16: =C26+C36 -> 42411.354 | D16: =D26+D36 -> 41564.601 | E16: =E36 -> 167.83476 | F16: =F26+F36 -> 626.32967 | G16: =G26+G36 -> 619.19512 | H16: =H26+H36 -> 2846.5286 | I16: =I26+I36 -> 1867.153 | J16: =(H16+I16)/M16 -> 0.095609407 | K16: =K26+K36 -> 93.439093 | L16: =L26+L36 -> 669.60752 | M16: =C16+E16+F16+G16+H16+I16+K16+L16 -> 49301.442 | N16: =C16/M16 -> 0.86024571
B17: =B16+1 -> 2008 | C17: =C27+C37 -> 34646.626 | D17: =D27+D37 -> 34497.057 | E17: =E37 -> 123.4548 | F17: =F27+F37 -> 606.70994 | G17: =G27+G37 -> 523.33192 | H17: =H27+H37 -> 2241.2158 | I17: =I27+I37 -> 1226.651 | J17: =(H17+I17)/M17 -> 0.086486339 | K17: =K27+K37 -> 58.478971 | L17: =L27+L37 -> 670.80985 | M17: =C17+E17+F17+G17+H17+I17+K17+L17 -> 40097.279 | N17: =C17/M17 -> 0.86406428
C18: Panel B: Equities
B20: 2001 | C20: =(RawDataSources!AS41)/1000 -> 6369.7175 | D20: =RawDataSources!AQ41/1000 -> 5566.1955 | F20: =RawDataSources!AU41/1000 -> 6.6351043 | G20: ='Table A12'!M8 -> 34.081699 | H20: {=TRANSPOSE('Table A6'!D31:K31)} -> 319.11253 | I20: {=TRANSPOSE('Table A10'!D15:K15)-TRANSPOSE('Table A10'!D8:K8)} -> 383.61876 | J20: =(H20+I20)/M20 -> 0.098611427 | K20: =RawDataSources!DE41/1000 -> 9.6685804 | L20: =RawDataSources!DC41/1000 -> 3.4321552 | M20: =C20+F20+G20+H20+I20+K20+L20 -> 7126.2663 | N20: =C20/M20 -> 0.89383658
B21: =B20+1 -> 2002 | C21: =(RawDataSources!AS42)/1000 -> 5863.2301 | D21: =RawDataSources!AQ42/1000 -> 5789.663 | F21: =RawDataSources!AU42/1000 -> 8.1766734 | G21: ='Table A12'!M9 -> 39.650186 | H21: 386.27653 | I21: 359.05778 | J21: =(H21+I21)/M21 -> 0.11166224 | K21: =RawDataSources!DE42/1000 -> 9.4675302 | L21: =RawDataSources!DC42/1000 -> 9.0412327 | M21: =C21+F21+G21+H21+I21+K21+L21 -> 6674.9 | N21: =C21/M21 -> 0.87839969
B22: =B21+1 -> 2003 | C22: =(RawDataSources!AS43)/1000 -> 8339.6884 | D22: =RawDataSources!AQ43/1000 -> 8135.3756 | F22: =RawDataSources!AU43/1000 -> 10.898422 | G22: ='Table A12'!M10 -> 62.790861 | H22: 561.1922 | I22: 493.68009 | J22: =(H22+I22)/M22 -> 0.11120482 | K22: =RawDataSources!DE43/1000 -> 9.3965396 | L22: =RawDataSources!DC43/1000 -> 8.2035312 | M22: =C22+F22+G22+H22+I22+K22+L22 -> 9485.85 | N22: =C22/M22 -> 0.87917144
B23: =B22+1 -> 2004 | C23: =(RawDataSources!AS44)/1000 -> 10222.688 | D23: =RawDataSources!AQ44/1000 -> 10020.618 | F23: =RawDataSources!AU44/1000 -> 11.989212 | G23: ='Table A12'!M11 -> 94.875301 | H23: 783.76227 | I23: 625.6866 | J23: =(H23+I23)/M23 -> 0.11975019 | K23: =RawDataSources!DE44/1000 -> 16.095909 | L23: =RawDataSources!DC44/1000 -> 14.812269 | M23: =C23+F23+G23+H23+I23+K23+L23 -> 11769.91 | N23: =C23/M23 -> 0.86854431
B24: =B23+1 -> 2005 | C24: =(RawDataSources!AS45)/1000 -> 12180.389 | D24: =RawDataSources!AQ45/1000 -> 11810.788 | F24: =RawDataSources!AU45/1000 -> 11.13755 | G24: ='Table A12'!M12 -> 300.51186 | H24: 856.52873 | I24: 757.20271 | J24: =(H24+I24)/M24 -> 0.11412137 | K24: =RawDataSources!DE45/1000 -> 18.76112 | L24: =RawDataSources!DC45/1000 -> 15.953787 | M24: =C24+F24+G24+H24+I24+K24+L24 -> 14140.485 | N24: =C24/M24 -> 0.86138412
B25: =B24+1 -> 2006 | C25: =(RawDataSources!AS46)/1000 -> 16005.888 | D25: =RawDataSources!AQ46/1000 -> 15337.555 | F25: =RawDataSources!AU46/1000 -> 42.537808 | G25: ='Table A12'!M13 -> 260.82035 | H25: 1195.0448 | I25: 988.31684 | J25: =(H25+I25)/M25 -> 0.11782381 | K25: =RawDataSources!DE46/1000 -> 25.641319 | L25: =RawDataSources!DC46/1000 -> 12.483933 | M25: =C25+F25+G25+H25+I25+K25+L25 -> 18530.733 | N25: =C25/M25 -> 0.86374824
B26: =B25+1 -> 2007 | C26: =(RawDataSources!AS47)/1000 -> 19195.122 | D26: =RawDataSources!AQ47/1000 -> 18281.582 | F26: =RawDataSources!AU47/1000 -> 18.458653 | G26: ='Table A12'!M14 -> 469.82941 | H26: 1669.3956 | I26: 1304.0603 | J26: =(H26+I26)/M26 -> 0.13092717 | K26: =RawDataSources!DE47/1000 -> 43.430713 | L26: =RawDataSources!DC47/1000 -> 10.465523 | M26: =C26+F26+G26+H26+I26+K26+L26 -> 22710.763 | N26: =C26/M26 -> 0.84519938
B27: =B26+1 -> 2008 | C27: =(RawDataSources!AS48)/1000 -> 11288.276 | D27: =RawDataSources!AQ48/1000 -> 11144.507 | F27: =RawDataSources!AU48/1000 -> 14.309453 | G27: ='Table A12'!M15 -> 472.30636 | H27: 1105.9018 | I27: 747.63123 | J27: =(H27+I27)/M27 -> 0.135667 | K27: =RawDataSources!DE48/1000 -> 20.458224 | L27: =RawDataSources!DC48/1000 -> 13.488853 | M27: =C27+F27+G27+H27+I27+K27+L27 -> 13662.372 | N27: =C27/M27 -> 0.82623105
C28: Panel C: Debt
B30: 2001 | C30: =(RawDataSources!AT41)/1000 -> 7685.744 | D30: =RawDataSources!AR41/1000 -> 7578.1689 | E30: =(RawDataSources!AY41+RawDataSources!AZ41)/1000 -> 35.256787 | F30: =RawDataSources!AV41/1000 -> 258.29617 | G30: ='Table A12'!M19 -> 208.22617 | H30: {=TRANSPOSE('Table A6'!D28:K28)} -> 389.262 | I30: {=TRANSPOSE('Table A11'!D15:K15)-TRANSPOSE('Table A11'!D8:K8)} -> 179.44312 | J30: =(H30+I30)/M30 -> 0.062178878 | K30: =RawDataSources!DF41/1000 -> 7.3727635 | L30: =RawDataSources!CY41+RawDataSources!CZ41 -> 382.674 | M30: =C30+F30+G30+H30+I30+K30+L30+E30 -> 9146.275 | N30: =C30/M30 -> 0.84031411 | O30: =RawDataSources!CW41 -> 7597.427 | P30: =D30/O30 -> 0.99746518
B31: =B30+1 -> 2002 | C31: =(RawDataSources!AT42)/1000 -> 9468.9885 | D31: =RawDataSources!AR42/1000 -> 9443.2761 | E31: =(RawDataSources!AY42+RawDataSources!AZ42)/1000 -> 30.771808 | F31: =RawDataSources!AV42/1000 -> 318.3075 | G31: ='Table A12'!M20 -> 158.76868 | H31: 451.832 | I31: 206.08164 | J31: =(H31+I31)/M31 -> 0.05938329 | K31: =RawDataSources!DF42/1000 -> 7.8848847 | L31: =RawDataSources!CY42+RawDataSources!CZ42 -> 436.469 | M31: =C31+F31+G31+H31+I31+K31+L31+E31 -> 11079.104 | N31: =C31/M31 -> 0.85467096 | O31: =RawDataSources!CW42 -> 9272.152 | P31: =D31/O31 -> 1.0184557
B32: =B31+1 -> 2003 | C32: =(RawDataSources!AT43)/1000 -> 12143.054 | D32: =RawDataSources!AR43/1000 -> 12120.97 | E32: =(RawDataSources!AY43+RawDataSources!AZ43)/1000 -> 47.144951 | F32: =RawDataSources!AV43/1000 -> 424.26171 | G32: ='Table A12'!M21 -> 205.8207 | H32: 529.0553 | I32: 286.60131 | J32: =(H32+I32)/M32 -> 0.057636721 | K32: =RawDataSources!DF43/1000 -> 9.7953754 | L32: =RawDataSources!CY43+RawDataSources!CZ43 -> 505.95 | M32: =C32+F32+G32+H32+I32+K32+L32+E32 -> 14151.683 | N32: =C32/M32 -> 0.85806428 | O32: =RawDataSources!CW43 -> 11702.099 | P32: =D32/O32 -> 1.0357945
B33: =B32+1 -> 2004 | C33: =(RawDataSources!AT44)/1000 -> 14977.046 | D33: =RawDataSources!AR44/1000 -> 14936.205 | E33: =(RawDataSources!AY44+RawDataSources!AZ44)/1000 -> 57.73496 | F33: =RawDataSources!AV44/1000 -> 446.46262 | G33: ='Table A12'!M22 -> 130.2576 | H33: 672.9417 | I33: 327.03025 | J33: =(H33+I33)/M33 -> 0.058204864 | K33: =RawDataSources!DF44/1000 -> 14.215794 | L33: =RawDataSources!CY44+RawDataSources!CZ44 -> 554.524 | M33: =C33+F33+G33+H33+I33+K33+L33+E33 -> 17180.213 | N33: =C33/M33 -> 0.87176137 | O33: =RawDataSources!CW44 -> 13934.547 | P33: =D33/O33 -> 1.0718831
B34: =B33+1 -> 2005 | C34: =(RawDataSources!AT45)/1000 -> 15982.269 | D34: =RawDataSources!AR45/1000 -> 15953.103 | E34: =(RawDataSources!AY45+RawDataSources!AZ45)/1000 -> 74.650013 | F34: =RawDataSources!AV45/1000 -> 382.66879 | G34: ='Table A12'!M23 -> 155.6869 | H34: 735.4636 | I34: 362.05994 | J34: =(H34+I34)/M34 -> 0.060111442 | K34: =RawDataSources!DF45/1000 -> 22.110739 | L34: =RawDataSources!CY45+RawDataSources!CZ45 -> 543.238 | M34: =C34+F34+G34+H34+I34+K34+L34+E34 -> 18258.147 | N34: =C34/M34 -> 0.87535 | O34: =RawDataSources!CW45 -> 14600.469 | P34: =D34/O34 -> 1.0926432
B35: =B34+1 -> 2006 | C35: =(RawDataSources!AT46)/1000 -> 19453.159 | D35: =RawDataSources!AR46/1000 -> 19354.194 | E35: =(RawDataSources!AY46+RawDataSources!AZ46)/1000 -> 103.84103 | F35: =RawDataSources!AV46/1000 -> 473.13253 | G35: ='Table A12'!M24 -> 169.0217 | H35: 946.7028 | I35: 442.4944 | J35: =(H35+I35)/M35 -> 0.062574029 | K35: =RawDataSources!DF46/1000 -> 25.953131 | L35: =RawDataSources!CY46+RawDataSources!CZ46 -> 586.554 | M35: =C35+F35+G35+H35+I35+K35+L35+E35 -> 22200.859 | N35: =C35/M35 -> 0.87623454 | O35: =RawDataSources!CW46 -> 18415.078 | P35: =D35/O35 -> 1.0509971
B36: =B35+1 -> 2007 | C36: =(RawDataSources!AT47)/1000 -> 23216.231 | D36: =RawDataSources!AR47/1000 -> 23283.019 | E36: =(RawDataSources!AY47+RawDataSources!AZ47)/1000 -> 167.83476 | F36: =RawDataSources!AV47/1000 -> 607.87102 | G36: ='Table A12'!M25 -> 149.3657 | H36: 1177.133 | I36: 563.09264 | J36: =(H36+I36)/M36 -> 0.065444949 | K36: =RawDataSources!DF47/1000 -> 50.008381 | L36: =RawDataSources!CY47+RawDataSources!CZ47 -> 659.142 | M36: =C36+F36+G36+H36+I36+K36+L36+E36 -> 26590.679 | N36: =C36/M36 -> 0.8730966 | O36: =RawDataSources!CW47 -> 22699.536 | P36: =D36/O36 -> 1.0257046
B37: =B36+1 -> 2008 | C37: =(RawDataSources!AT48)/1000 -> 23358.351 | D37: =RawDataSources!AR48/1000 -> 23352.551 | E37: =(RawDataSources!AY48+RawDataSources!AZ48)/1000 -> 123.4548 | F37: =RawDataSources!AV48/1000 -> 592.40049 | G37: ='Table A12'!M26 -> 51.025563 | H37: 1135.314 | I37: 479.0198 | J37: =(H37+I37)/M37 -> 0.061068261 | K37: =RawDataSources!DF48/1000 -> 38.020747 | L37: =RawDataSources!CY48+RawDataSources!CZ48 -> 657.321 | M37: =C37+F37+G37+H37+I37+K37+L37+E37 -> 26434.907 | N37: =C37/M37 -> 0.88361766 | O37: =RawDataSources!CW48 -> 23845.355 | P37: =D37/O37 -> 0.97933331
H51: .

Sheet Table A3
B2: Table A3 – Global Discrepancy Between Cross-Border Securities Assets and Liabilities
C3: [1] | D3: [2] | E3: [3] | F3: [4] | G3: [5] | H3: [6] | I3: [7] | J3: [9] | K3: [10] | L3: [11] | M3: [12] | N3: [13] | O3: [14] | P3: [15]
C4: Billions of current USD
C5: Global Securities Assets | D5: Global Securities Liabilities | E5: Discrepancy | F5: Where the missing securities are invested: Lj - ΣiÂij | M5: Offshore asset allocation | O5: World market cap
F6: Luxembourg | G6: Cayman islands | H6: Ireland | I6: United States | J6: Japan | K6: Swtizerland | L6: Other | N6: Missing wealth / Cross-border securities | P6: Missing wealth / World market cap
C7: ΣiΣj Âij | D7: ΣjLj | E7: Ω = ΣjLj- ΣiΣj Âij
C8: Panel A: All securities
B10: 2001 | C10: ='Table A1'!O11 -> 13740.57 | D10: ='Table A2'!M10 -> 16272.541 | E10: =D10-C10 -> 2531.9709 | F10: =F20+F30 -> 305.34753 | G10: =G20+G30 -> 264.64353 | H10: =H20+H30 -> 165.33253 | I10: =I20+I30 -> 509.09488 | J10: =J20+J30 -> 93.42358 | K10: =K20+K30 -> 124.79165 | L10: =E10-SUM(F10:K10) -> 1069.3372 | N10: =E10/D10 -> 0.15559775 | O10: =O20+O30 -> 65130.164
B11: =B10+1 -> 2002 | C11: ='Table A1'!O12 -> 15361.99 | D11: ='Table A2'!M11 -> 17754.004 | E11: =D11-C11 -> 2392.014 | F11: =F21+F31 -> 361.75921 | G11: =G21+G31 -> 273.88684 | H11: =H21+H31 -> 219.89196 | I11: =I21+I31 -> 401.44325 | J11: =J21+J31 -> 69.66098 | K11: =K21+K31 -> 112.60689 | L11: =E11-SUM(F11:K11) -> 952.76483 | N11: =E11/D11 -> 0.13473096 | O11: =O21+O31 -> 66086.243
B12: =B11+1 -> 2003 | C12: ='Table A1'!O13 -> 20779.851 | D12: ='Table A2'!M12 -> 23637.533 | E12: =D12-C12 -> 2857.6815 | F12: =F22+F32 -> 464.88133 | G12: =G22+G32 -> 346.50519 | H12: =H22+H32 -> 314.3389 | I12: =I22+I32 -> 494.99675 | J12: =J22+J32 -> 93.63187 | K12: =K22+K32 -> 131.20942 | L12: =E12-SUM(F12:K12) -> 1012.1181 | N12: =E12/D12 -> 0.12089593 | O12: =O22+O32 -> 82453.152
B13: =B12+1 -> 2004 | C13: ='Table A1'!O14 -> 25634.097 | D13: ='Table A2'!M13 -> 28950.123 | E13: =D13-C13 -> 3316.0255 | F13: =F23+F33 -> 570.22168 | G13: =G23+G33 -> 476.65731 | H13: =H23+H33 -> 432.90675 | I13: =I23+I33 -> 539.24112 | J13: =J23+J33 -> 150.56893 | K13: =K23+K33 -> 146.66477 | L13: =E13-SUM(F13:K13) -> 999.76498 | N13: =E13/D13 -> 0.11454271 | O13: =O23+O33 -> 95686.193
B14: =B13+1 -> 2005 | C14: ='Table A1'!O15 -> 28722.994 | D14: ='Table A2'!M14 -> 32398.632 | E14: =D14-C14 -> 3675.6375 | F14: =F24+F34 -> 733.31638 | G14: =G24+G34 -> 462.87628 | H14: =H24+H34 -> 515.3299 | I14: =I24+I34 -> 491.82588 | J14: =J24+J34 -> 188.09078 | K14: =K24+K34 -> 136.1833 | L14: =E14-SUM(F14:K14) -> 1148.015 | N14: =E14/D14 -> 0.11345039 | O14: =O24+O34 -> 102464.65
B15: =B14+1 -> 2006 | C15: ='Table A1'!O16 -> 36971.589 | D15: ='Table A2'!M15 -> 40731.592 | E15: =D15-C15 -> 3760.0032 | F15: =F25+F35 -> 766.36747 | G15: =G25+G35 -> 559.29925 | H15: =H25+H35 -> 526.87332 | I15: =I25+I35 -> 354.271 | J15: =J25+J35 -> 230.54982 | K15: =K25+K35 -> 135.42891 | L15: =E15-SUM(F15:K15) -> 1187.2134 | N15: =E15/D15 -> 0.092311715 | O15: =O25+O35 -> 121337.5
B16: =B15+1 -> 2007 | C16: ='Table A1'!O17 -> 44170.116 | D16: ='Table A2'!M16 -> 49301.442 | E16: =D16-C16 -> 5131.3254 | F16: =F26+F36 -> 1039.0949 | G16: =G26+G36 -> 856.5045 | H16: =H26+H36 -> 681.60718 | I16: =I26+I36 -> 264.195 | J16: =J26+J36 -> 359.77703 | K16: =K26+K36 -> 109.75598 | L16: =E16-SUM(F16:K16) -> 1820.3908 | N16: =E16/D16 -> 0.10408064 | O16: =O26+O36 -> 143297.27
B17: =B16+1 -> 2008 | C17: ='Table A1'!O18 -> 35607.301 | D17: ='Table A2'!M17 -> 40097.279 | E17: =D17-C17 -> 4489.9776 | F17: =F27+F37 -> 911.55479 | G17: =G27+G37 -> 840.69737 | H17: =H27+H37 -> 603.17981 | I17: =I27+I37 -> 209.85375 | J17: =J27+J37 -> 291.22925 | K17: =K27+K37 -> 97.87104 | L17: =E17-SUM(F17:K17) -> 1535.5916 | N17: =E17/D17 -> 0.11197711 | O17: =O27+O37 -> 119079.84
C18: Panel B: Equities
B20: 2001 | C20: ='Table A1'!O21 -> 5553.6765 | D20: ='Table A2'!M20 -> 7126.2663 | E20: =D20-C20 -> 1572.5898 | F20: {=TRANSPOSE('Table A13'!B127:I127)} -> 310.92106 | G20: {=TRANSPOSE('Table A13'!B42:I42)} -> 202.65172 | H20: {=TRANSPOSE('Table A13'!B104:I104)} -> 175.07469 | I20: {=TRANSPOSE('Table A13'!B226:I226)} -> 411.12238 | J20: {=TRANSPOSE('Table A13'!B109:I109)} -> 36.54094 | K20: {=TRANSPOSE('Table A13'!B205:I205)} -> 115.71523 | L20: =E20-SUM(F20:K20) -> 320.56379 | M20: =E20/E10 -> 0.62109317 | N20: =E20/D20 -> 0.22067514 | O20: 27906.618 | P20: =E20/O20 -> 0.056351859
B21: =B20+1 -> 2002 | C21: ='Table A1'!O22 -> 5173.8457 | D21: ='Table A2'!M21 -> 6674.9 | E21: =D21-C21 -> 1501.0543 | F21: 368.30819 | G21: 252.18184 | H21: 225.58658 | I21: 298.5475 | J21: 26.97675 | K21: 106.15664 | L21: =E21-SUM(F21:K21) -> 223.29681 | M21: =E21/E11 -> 0.62752741 | N21: =E21/D21 -> 0.22488042 | O21: 23509.657 | P21: =E21/O21 -> 0.063848414
B22: =B21+1 -> 2003 | C22: ='Table A1'!O23 -> 7546.0951 | D22: ='Table A2'!M22 -> 9485.85 | E22: =D22-C22 -> 1939.755 | F22: 475.6965 | G22: 346.50519 | H22: 316.18781 | I22: 340.68575 | J22: 52.99459 | K22: 116.6525 | L22: =E22-SUM(F22:K22) -> 291.03261 | M22: =E22/E12 -> 0.67878626 | N22: =E22/D22 -> 0.20448931 | O22: 32036.7 | P22: =E22/O22 -> 0.060547901
B23: =B22+1 -> 2004 | C23: ='Table A1'!O24 -> 9425.5596 | D23: ='Table A2'!M23 -> 11769.91 | E23: =D23-C23 -> 2344.3501 | F23: 582.21006 | G23: 476.65731 | H23: 385.52834 | I23: 381.82612 | J23: 72.43281 | K23: 122.09516 | L23: =E23-SUM(F23:K23) -> 323.6003 | M23: =E23/E13 -> 0.70697589 | N23: =E23/D23 -> 0.19918166 | O23: 38151.94 | P23: =E23/O23 -> 0.06144773
B24: =B23+1 -> 2005 | C24: ='Table A1'!O25 -> 11421.045 | D24: ='Table A2'!M24 -> 14140.485 | E24: =D24-C24 -> 2719.4393 | F24: 746.53288 | G24: 462.87628 | H24: 441.24312 | I24: 279.15138 | J24: 134.96894 | K24: 117.00569 | L24: =E24-SUM(F24:K24) -> 537.66103 | M24: =E24/E14 -> 0.73985514 | N24: =E24/D24 -> 0.19231585 | O24: 43319.352 | P24: =E24/O24 -> 0.062776547
B25: =B24+1 -> 2006 | C25: ='Table A1'!O26 -> 15511.1 | D25: ='Table A2'!M25 -> 18530.733 | E25: =D25-C25 -> 3019.6332 | F25: 780.56838 | G25: 559.29925 | H25: 523.55944 | I25: 186.756 | J25: 125.04238 | K25: 110.56594 | L25: =E25-SUM(F25:K25) -> 733.84185 | M25: =E25/E15 -> 0.80309327 | N25: =E25/D25 -> 0.16295271 | O25: 53375.287 | P25: =E25/O25 -> 0.056573621
B26: =B25+1 -> 2007 | C26: ='Table A1'!O27 -> 18738.356 | D26: ='Table A2'!M26 -> 22710.763 | E26: =D26-C26 -> 3972.407 | F26: 1060 | G26: 797.87325 | H26: 706.45712 | I26: 192.087 | J26: 149.70762 | K26: 101.46438 | L26: =E26-SUM(F26:K26) -> 964.81765 | M26: =E26/E16 -> 0.77414834 | N26: =E26/D26 -> 0.17491297 | O26: 64563.414 | P26: =E26/O26 -> 0.061527214
B27: =B26+1 -> 2008 | C27: ='Table A1'!O28 -> 10846.197 | D27: ='Table A2'!M27 -> 13662.372 | E27: =D27-C27 -> 2816.1746 | F27: 929.79938 | G27: 599.52825 | H27: 636.667 | I27: 177.02875 | J27: 49.89669 | K27: 93.86097 | L27: =E27-SUM(F27:K27) -> 329.39358 | M27: =E27/E17 -> 0.62721352 | N27: =E27/D27 -> 0.20612633 | O27: 35811.16 | P27: =E27/O27 -> 0.078639581
C28: Panel C: Debt
B30: 2001 | C30: ='Table A1'!O31 -> 8186.8939 | D30: ='Table A2'!M30 -> 9146.275 | E30: =D30-C30 -> 959.38105 | F30: {=TRANSPOSE('Table A14'!B127:I127)} -> -5.57353 | G30: {=TRANSPOSE('Table A14'!B42:I42)} -> 61.99181 | H30: {=TRANSPOSE('Table A14'!B104:I104)} -> -9.74216 | I30: {=TRANSPOSE('Table A14'!B226:I226)} -> 97.9725 | J30: {=TRANSPOSE('Table A14'!B109:I109)} -> 56.88264 | K30: {=TRANSPOSE('Table A14'!B205:I205)} -> 9.07642 | L30: =E30-SUM(F30:K30) -> 748.77337 | M30: =E30/E10 -> 0.37890683 | N30: =E30/D30 -> 0.10489309 | O30: 37223.546 | P30: =E30/O30 -> 0.0257735
B31: =B30+1 -> 2002 | C31: ='Table A1'!O32 -> 10188.144 | D31: ='Table A2'!M31 -> 11079.104 | E31: =D31-C31 -> 890.95964 | F31: -6.54898 | G31: 21.705 | H31: -5.69462 | I31: 102.89575 | J31: 42.68423 | K31: 6.45025 | L31: =E31-SUM(F31:K31) -> 729.46801 | M31: =E31/E11 -> 0.37247259 | N31: =E31/D31 -> 0.080418023 | O31: 42576.586 | P31: =E31/O31 -> 0.020926047
B32: =B31+1 -> 2003 | C32: ='Table A1'!O33 -> 13233.756 | D32: ='Table A2'!M32 -> 14151.683 | E32: =D32-C32 -> 917.92659 | F32: -10.81517 | G32: 0 | H32: -1.84891 | I32: 154.311 | J32: 40.63728 | K32: 14.55692 | L32: =E32-SUM(F32:K32) -> 721.08547 | M32: =E32/E12 -> 0.32121374 | N32: =E32/D32 -> 0.064863422 | O32: 50416.452 | P32: =E32/O32 -> 0.018206886
B33: =B32+1 -> 2004 | C33: ='Table A1'!O34 -> 16208.538 | D33: ='Table A2'!M33 -> 17180.213 | E33: =D33-C33 -> 971.67544 | F33: -11.98838 | G33: 0 | H33: 47.37841 | I33: 157.415 | J33: 78.13612 | K33: 24.56961 | L33: =E33-SUM(F33:K33) -> 676.16468 | M33: =E33/E13 -> 0.29302411 | N33: =E33/D33 -> 0.056557822 | O33: 57534.253 | P33: =E33/O33 -> 0.016888643
B34: =B33+1 -> 2005 | C34: ='Table A1'!O35 -> 17301.949 | D34: ='Table A2'!M34 -> 18258.147 | E34: =D34-C34 -> 956.19819 | F34: -13.2165 | G34: 0 | H34: 74.08678 | I34: 212.6745 | J34: 53.12184 | K34: 19.17761 | L34: =E34-SUM(F34:K34) -> 610.35396 | M34: =E34/E14 -> 0.26014486 | N34: =E34/D34 -> 0.052371043 | O34: 59145.298 | P34: =E34/O34 -> 0.016166935
B35: =B34+1 -> 2006 | C35: ='Table A1'!O36 -> 21460.489 | D35: ='Table A2'!M35 -> 22200.859 | E35: =D35-C35 -> 740.36991 | F35: -14.20091 | G35: 0 | H35: 3.31388 | I35: 167.515 | J35: 105.50744 | K35: 24.86297 | L35: =E35-SUM(F35:K35) -> 453.37153 | M35: =E35/E15 -> 0.19690673 | N35: =E35/D35 -> 0.033348705 | O35: 67962.213 | P35: =E35/O35 -> 0.010893846
B36: =B35+1 -> 2007 | C36: ='Table A1'!O37 -> 25431.761 | D36: ='Table A2'!M36 -> 26590.679 | E36: =D36-C36 -> 1158.9183 | F36: -20.90509 | G36: 58.63125 | H36: -24.84994 | I36: 72.108 | J36: 210.06941 | K36: 8.2916 | L36: =E36-SUM(F36:K36) -> 855.57312 | M36: =E36/E16 -> 0.22585166 | N36: =E36/D36 -> 0.043583631 | O36: 78733.854 | P36: =E36/O36 -> 0.014719441
B37: =B36+1 -> 2008 | C37: ='Table A1'!O38 -> 24761.104 | D37: ='Table A2'!M37 -> 26434.907 | E37: =D37-C37 -> 1673.8029 | F37: -18.24459 | G37: 241.16912 | H37: -33.48719 | I37: 32.825 | J37: 241.33256 | K37: 4.01007 | L37: =E37-SUM(F37:K37) -> 1206.198 | M37: =E37/E17 -> 0.37278648 | N37: =E37/D37 -> 0.063317905 | O37: 83268.678 | P37: =E37/O37 -> 0.020101231

Sheet Table A4
B2: Table A4: Main Holders of Cross-Border Securities
C3: [1] | D3: [2] | E3: [3] | F3: [4] | G3: [5] | H3: [6] | I3: [7] | J3: [8] | K3: [9] | L3: [10] | M3: [11] | N3: [12] | O3: [13] | P3: [14] | Q3: [15] | R3: [16]
C4: Billions of current USD
C5: Industrial, emerging and developing countries | K5: Memo: Unknown Owner (Ω) | L5: Offshore financial centers
C6: United States | D6: United Kingdom | E6: Japan | F6: Germany | G6: France | H6: Other (private) | I6: Reserve + Int'l orga. | J6: Total onshore | L6: Luxem-bourg | M6: Ireland | N6: Cayman Islands | O6: Bermuda | P6: Hong-Kong | Q6: Other | R6: Total offshore centers
C8: Panel A: All securities
B10: 2001 | C10: =C20+C30 -> 2303.6035 | D10: =D20+D30 -> 1304.0445 | E10: =E20+E30 -> 1289.7541 | F10: =F20+F30 -> 791.61626 | G10: =G20+G30 -> 710.33044 | H10: =H20+H30 -> 2749.7028 | I10: =I20+I30 -> 1700.3726 | J10: =J20+J30 -> 10849.424 | ... R10: =R20+R30 -> 2891.1464
B11: =B10+1 -> 2002 | C11: =C21+C31 -> 2246.0338 | D11: =D21+D31 -> 1360.3801 | E11: =E21+E31 -> 1394.5197 | F11: =F21+F31 -> 897.83191 | G11: =G21+G31 -> 931.87644 | H11: =H21+H31 -> 3166.3907 | I11: =I21+I31 -> 1958.0927 | J11: =J21+J31 -> 11955.125 | ... R11: =R21+R31 -> 3406.8645
B12: =B11+1 -> 2003 | C12: =C22+C32 -> 3134.244 | D12: =D22+D32 -> 1670.2043 | E12: =E22+E32 -> 1721.3143 | F12: =F22+F32 -> 1205.1268 | G12: =G22+G32 -> 1369.5769 | H12: =H22+H32 -> 4412.0923 | I12: =I22+I32 -> 2542.6836 | J12: =J22+J32 -> 16055.242 | ... R12: =R22+R32 -> 4724.6093
B13: =B12+1 -> 2004 | C13: =C23+C33 -> 3764.3509 | D13: =D23+D33 -> 2109.701 | E13: =E23+E33 -> 2009.6724 | F13: =F23+F33 -> 1515.4765 | G13: =G23+G33 -> 1750.7056 | H13: =H23+H33 -> 5524.9397 | I13: =I23+I33 -> 3096.0829 | J13: =J23+J33 -> 19770.929 | ... R13: =R23+R33 -> 5863.1682
B14: =B13+1 -> 2005 | C14: =C24+C34 -> 4591.122 | D14: =D24+D34 -> 2373.9237 | E14: =E24+E34 -> 2114.8893 | F14: =F24+F34 -> 1552.8026 | G14: =G24+G34 -> 1873.2591 | H14: =H24+H34 -> 6290.4059 | I14: =I24+I34 -> 3418.384 | J14: =J24+J34 -> 22214.787 | ... R14: =R24+R34 -> 6508.2076
B15: =B14+1 -> 2006 | C15: =C25+C35 -> 5972.356 | D15: =D25+D35 -> 3140.5095 | E15: =E25+E35 -> 2343.4824 | F15: =F25+F35 -> 2310.3827 | G15: =G25+G35 -> 2463.9596 | H15: =H25+H35 -> 7980.0337 | I15: =I25+I35 -> 4082.9576 | J15: =J25+J35 -> 28293.681 | ... R15: =R25+R35 -> 8677.9078
B16: =B15+1 -> 2007 | C16: =C26+C36 -> 7191.779 | D16: =D26+D36 -> 3393.411 | E16: =E26+E36 -> 2523.5667 | F16: =F26+F36 -> 2624.8058 | G16: =G26+G36 -> 2964.9952 | H16: =H26+H36 -> 9656.1799 | I16: =I26+I36 -> 5194.7425 | J16: =J26+J36 -> 33549.48 | ... R16: =R26+R36 -> 10620.636
B17: =B16+1 -> 2008 | C17: =C27+C37 -> 4267.865 | D17: =D27+D37 -> 2426.2515 | E17: =E27+E37 -> 2376.6061 | F17: =F27+F37 -> 2149.155 | G17: =G27+G37 -> 2553.3653 | H17: =H27+H37 -> 7583.5533 | I17: =I27+I37 -> 6124.3972 | J17: =J27+J37 -> 27481.193 | ... R17: =R27+R37 -> 8126.1078
C18: Panel B: Equities
B20: 2001 | C20: 1612.667 | D20: 558.37932 | E20: 227.3514 | F20: 381.18429 | G20: 201.7516 | H20: =J20-I20-SUM(C20:G20) -> 1359.4613 | I20: ='Table A1'!P21 -> 45.706618 | J20: ='Table A1'!O21-R20 -> 4386.5015 | K20: ='Table A3'!E20 -> 1572.5898 | L20: 319.09314 | M20: 133.7549 | N20: 163.9546 | O20: 31.03212 | P20: 94.615 | Q20: =R20-N20-M20-L20-O20-P20 -> 424.72519 | R20: 1167.1749
B21: =B20+1 -> 2002 | C21: 1385.3587 | D21: 493.03513 | E21: 210.81728 | F21: 331.22875 | G21: 200.09415 | H21: =J21-I21-SUM(C21:G21) -> 1305.2524 | I21: ='Table A1'!P22 -> 42.731351 | J21: ='Table A1'!O22-R21 -> 3968.5177 | K21: ='Table A3'!E21 -> 1501.0543 | L21: 304.99659 | M21: 152.85641 | N21: 202.23221 | O21: 30.99825 | P21: 95.721 | Q21: =R21-N21-M21-L21-O21-P21 -> 418.52348 | R21: 1205.3279
B22: =B21+1 -> 2003 | C22: 2080.302 | D22: 663.8727 | E22: 274.45717 | F22: 440.81351 | G22: 340.24034 | H22: =J22-I22-SUM(C22:G22) -> 1860.5773 | I22: ='Table A1'!P23 -> 63.842141 | J22: ='Table A1'!O23-R22 -> 5724.1052 | K22: ='Table A3'!E22 -> 1939.755 | L22: 488.24 | M22: 223.38601 | N22: 339.49899 | O22: 62.03767 | P22: 152.831 | Q22: =R22-N22-M22-L22-O22-P22 -> 555.99624 | R22: 1821.9899
B23: =B22+1 -> 2004 | C23: 2560.4179 | D23: 879.34131 | E23: 364.69028 | F23: 523.83371 | G23: 442.65451 | H23: =J23-I23-SUM(C23:G23) -> 2285.2507 | I23: ='Table A1'!P24 -> 81.65537 | J23: ='Table A1'!O24-R23 -> 7137.8438 | K23: ='Table A3'!E23 -> 2344.3501 | L23: 637.83661 | M23: 304.94285 | N23: 403.84999 | O23: 64.58507 | P23: 199.671 | Q23: =R23-N23-M23-L23-O23-P23 -> 676.83031 | R23: 2287.7158
B24: =B23+1 -> 2005 | C24: 3317.705 | D24: 1075.9968 | E24: 408.5748 | F24: 529.08603 | G24: 524.8873 | H24: =J24-I24-SUM(C24:G24) -> 2739.4861 | I24: ='Table A1'!P25 -> 91.950951 | J24: ='Table A1'!O25-R24 -> 8687.687 | K24: ='Table A3'!E24 -> 2719.4393 | L24: 807.86584 | M24: 383.15477 | N24: 431.90524 | O24: 87.31782 | P24: 227.8341 | Q24: =R24-N24-M24-L24-O24-P24 -> 795.28066 | R24: 2733.3584
B25: =B24+1 -> 2006 | C25: 4328.962 | D25: 1366.4816 | E25: 510.41842 | F25: 928.24397 | G25: 743.02358 | H25: =J25-I25-SUM(C25:G25) -> 3632.6086 | I25: ='Table A1'!P26 -> 127.1112 | J25: ='Table A1'!O26-R25 -> 11636.849 | K25: ='Table A3'!E25 -> 3019.6332 | L25: 1148.2134 | M25: 573.19921 | N25: 618.02803 | O25: 113.92202 | P25: 338.877 | Q25: =R25-N25-M25-L25-O25-P25 -> 1082.0111 | R25: 3874.2508
B26: =B25+1 -> 2007 | C26: 5247.983 | D26: 1508.7104 | E26: 573.46946 | F26: 954.02532 | G26: 826.85822 | H26: =J26-I26-SUM(C26:G26) -> 4482.4554 | I26: ='Table A1'!P27 -> 233.8888 | J26: ='Table A1'!O27-R26 -> 13827.391 | K26: ='Table A3'!E26 -> 3972.407 | L26: 1413.2355 | M26: 649.17252 | N26: 775.6991 | O26: 138.29469 | P26: 514.511 | Q26: =R26-N26-M26-L26-O26-P26 -> 1420.0523 | R26: 4910.9651
B27: =B26+1 -> 2008 | C27: 2748.428 | D27: 824.01854 | E27: 394.67768 | F27: 589.52134 | G27: 454.68896 | H27: =J27-I27-SUM(C27:G27) -> 2707.696 | I27: ='Table A1'!P28 -> 178.03488 | J27: ='Table A1'!O28-R27 -> 7897.0654 | K27: ='Table A3'!E27 -> 2816.1746 | L27: 757.73893 | M27: 431.02619 | N27: 458.84723 | O27: 81.298 | P27: 275.1598 | Q27: =R27-N27-M27-L27-O27-P27 -> 945.06165 | R27: 2949.1318
C28: Panel C: Debt
B30: 2001 | C30: 690.93649 | D30: 745.66517 | E30: 1062.4027 | F30: 410.43197 | G30: 508.57884 | H30: =J30-I30-SUM(C30:G30) -> 1390.2415 | I30: ='Table A1'!P31 -> 1654.6659 | J30: ='Table A1'!O31-'Table A4'!R30 -> 6462.9225 | K30: ='Table A3'!E30 -> 959.38105 | L30: 501.52105 | M30: 299.08415 | N30: 178.51814 | O30: 131.40045 | P30: 178.51814 | Q30: =R30-N30-M30-L30-O30-P30 -> 434.92949 | R30: 1723.9714
B31: =B30+1 -> 2002 | C31: 860.67516 | D31: 867.34502 | E31: 1183.7024 | F31: 566.60316 | G31: 731.78229 | H31: =J31-I31-SUM(C31:G31) -> 1861.1383 | I31: ='Table A1'!P32 -> 1915.3613 | J31: ='Table A1'!O32-'Table A4'!R31 -> 7986.6078 | K31: ='Table A3'!E31 -> 890.95964 | L31: 618.40217 | M31: 421.11069 | N31: 224.12985 | O31: 156.67277 | P31: 224.12985 | Q31: =R31-N31-M31-L31-O31-P31 -> 557.09127 | R31: 2201.5366
B32: =B31+1 -> 2003 | C32: 1053.942 | D32: 1006.3316 | E32: 1446.8571 | F32: 764.31326 | G32: 1029.3365 | H32: =J32-I32-SUM(C32:G32) -> 2551.515 | I32: ='Table A1'!P33 -> 2478.8414 | J32: ='Table A1'!O33-'Table A4'!R32 -> 10331.137 | K32: ='Table A3'!E32 -> 917.92659 | L32: 844.96351 | M32: 612.4093 | N32: 278.69177 | O32: 191.94021 | P32: 278.69177 | Q32: =R32-N32-M32-L32-O32-P32 -> 695.92286 | R32: 2902.6194
B33: =B32+1 -> 2004 | C33: 1203.933 | D33: 1230.3597 | E33: 1644.9821 | F33: 991.64284 | G33: 1308.0511 | H33: =J33-I33-SUM(C33:G33) -> 3239.689 | I33: ='Table A1'!P34 -> 3014.4275 | J33: ='Table A1'!O34-'Table A4'!R33 -> 12633.085 | K33: ='Table A3'!E33 -> 971.67544 | L33: 978.47692 | M33: 767.36899 | N33: 453.9021 | O33: 245.07271 | P33: 453.9021 | Q33: =R33-N33-M33-L33-O33-P33 -> 676.72951 | R33: 3575.4523
B34: =B33+1 -> 2005 | C34: 1273.417 | D34: 1297.9269 | E34: 1706.3146 | F34: 1023.7166 | G34: 1348.3718 | H34: =J34-I34-SUM(C34:G34) -> 3550.9198 | I34: ='Table A1'!P35 -> 3326.433 | J34: ='Table A1'!O35-'Table A4'!R34 -> 13527.1 | K34: ='Table A3'!E34 -> 956.19819 | L34: 1033.0554 | M34: 799.05681 | N34: 479.5053 | O34: 304.81555 | P34: 479.5053 | Q34: =R34-N34-M34-L34-O34-P34 -> 678.91087 | R34: 3774.8492
B35: =B34+1 -> 2006 | C35: 1643.394 | D35: 1774.0279 | E35: 1833.064 | F35: 1382.1388 | G35: 1720.936 | H35: =J35-I35-SUM(C35:G35) -> 4347.4251 | I35: ='Table A1'!P36 -> 3955.8464 | J35: ='Table A1'!O36-'Table A4'!R35 -> 16656.832 | K35: ='Table A3'!E35 -> 740.36991 | L35: 1282.7064 | M35: 1047.019 | N35: 716.45899 | O35: 334.7388 | P35: 716.45899 | Q35: =R35-N35-M35-L35-O35-P35 -> 706.27483 | R35: 4803.657
B36: =B35+1 -> 2007 | C36: 1943.796 | D36: 1884.7006 | E36: 1950.0972 | F36: 1670.7805 | G36: 2138.137 | H36: =J36-I36-SUM(C36:G36) -> 5173.7245 | I36: ='Table A1'!P37 -> 4960.8537 | J36: ='Table A1'!O37-'Table A4'!R36 -> 19722.09 | K36: ='Table A3'!E36 -> 1158.9183 | L36: 1469.3712 | M36: 1321.2951 | N36: 858.05975 | O36: 435.41283 | P36: 858.05975 | Q36: =R36-N36-M36-L36-O36-P36 -> 767.4724 | R36: 5709.6711
B37: =B36+1 -> 2008 | C37: 1519.437 | D37: 1602.233 | E37: 1981.9284 | F37: 1559.6337 | G37: 2098.6764 | H37: =J37-I37-SUM(C37:G37) -> 4875.8574 | I37: ='Table A1'!P38 -> 5946.3623 | J37: ='Table A1'!O38-'Table A4'!R37 -> 19584.128 | K37: ='Table A3'!E37 -> 1673.8029 | L37: 1362.4646 | M37: 1195.7793 | N37: 793.85869 | O37: 314.771 | P37: 793.85869 | Q37: =R37-N37-M37-L37-O37-P37 -> 716.24374 | R37: 5176.976

Sheet Table A5
A1: Table A5: Sectoral Breakdown of Portfolio Claims Reported in the CPIS, 2008
B3: Public sector | C3: Private sector
C4: Total | D4: Of which: banks | E4: Of which: non banks
A5: Argentina | B5: 0.0712987 | C5: =1-B5 -> 0.9287013 | D5: 0.0006427 | E5: 0.9280587
A6: Australia | B6: 0.0449511 | C6: =1-B6 -> 0.9550489 | D6: 0.0536148 | E6: 0.9014341
A7: Austria | B7: 0.0520882 | C7: =1-B7 -> 0.9479118 | D7: 0.3909276 | E7: 0.5569842
A8: Bahrain | B8: 0.0218008 | C8: =1-B8 -> 0.9781992 | D8: 0.9507242 | E8: 0.027475
A9: Barbados | B9: 0 | C9: =1-B9 -> 1 | D9: 1 | E9: 0
A10: Bermuda | B10: 0.0032949 | C10: =1-B10 -> 0.9967051 | D10: 0.0120232 | E10: 0.984682
A11: Bulgaria | B11: 0 | C11: =1-B11 -> 1 | D11: 0.4958141 | E11: 0.5041859
A12: Cayman Islands | B12: 0 | C12: =1-B12 -> 1 | D12: 1 | E12: 0
A13: Chile | B13: 0.3315388 | C13: =1-B13 -> 0.6684612 | D13: 0.0087065 | E13: 0.6597546
A14: Colombia | B14: 0.114978 | C14: =1-B14 -> 0.885022 | D14: 0.0091577 | E14: 0.8758643
A15: Costa Rica | B15: 0 | C15: =1-B15 -> 1 | D15: 0.4363366 | E15: 0.5636634
A16: Cyprus | B16: 0.0001096 | C16: =1-B16 -> 0.9998904 | D16: 0.9369113 | E16: 0.0629791
... A52: Venezuela | B52: 0.6503981 | C52: =1-B52 -> 0.3496019 | D52: 0.1367036 | E52: 0.2128983
A53: Weighted Mean | B53: 0.081367775 | C53: =1-B53 -> 0.91863223 | D53: 0.25378515 | E53: =1-D53-B53 -> 0.66484708

Sheet Table A6
B2: Table A6: Portfolio Assets and Liabilities of the Cayman Islands (bn of USD)
D4: 2001 | E4: 2002 | F4: 2003 | G4: 2004 | H4: 2005 | I4: 2006 | J4: 2007 | K4: 2008
B6: [1] | C6: Holdings of U.S. securities (TIC) | D6: =D7+D8+D9 -> 159.54662 | E6: =E7+E8+E9 -> 193.59021 | F6: =F7+F8+F9 -> 276.457 | G6: =G7+G8+G9 -> 400.553 | H6: =H7+H8+H9 -> 445.233 | I6: =I7+I8+I9 -> 645.993 | J6: =J7+J8+J9 -> 851.468 | K6: =K7+K8+K9 -> 706.376
B7: [2] | C7: Equities | D7: 57.128 | E7: 65.171 | F7: 116.663 | G7: 139.966 | H7: 165.426 | I7: 220.741 | J7: 329.207 | K7: 212.798
B8: [3] | C8: Long term debt | D8: 91.895 | E8: 115.224 | F8: 143.375 | G8: 226.579 | H8: 255.177 | I8: 385.628 | J8: 468.733 | K8: 410.226
B9: [4] | C9: Short term debt | D9: 10.52362 | E9: 13.195207 | F9: 16.419 | G9: 34.008 | H9: 24.63 | I9: 39.624 | J9: 53.528 | K9: 83.352
B10: [5] | C10: Estimated share of U.S. securities (gravity)
B11: [6] | C11: Equities | D11: 0.3484379 | E11: 0.3222583 | F11: 0.3436328 | G11: 0.3465792 | H11: 0.3830146 | I11: 0.3571699 | J11: 0.4244004 | K11: 0.4637665
B12: [7] | C12: Debt | D12: 0.5737176 | E12: 0.572967 | F12: 0.5733718 | G12: 0.574104 | H12: 0.5835326 | I12: 0.5935469 | J12: 0.6086534 | K12: 0.6217454
B14: [8] | C14: Total assets (est. from TIC + gravity) | D14: =D15+D16 -> 342.47209 | E14: =E15+E16 -> 426.36238 | F14: =F15+F16 -> 618.19079 | G14: =G15+G16 -> 857.75205 | H14: =H15+H16 -> 911.41055 | I14: =I15+I16 -> 1334.487 | J14: =J15+J16 -> 1633.7589 | K14: =K15+K16 -> 1252.706
B15: [9] | C15: Of which: equities | D15: =D7/D11 -> 163.95461 | E15: =E7/E11 -> 202.23218 | F15: =F7/F11 -> 339.49902 | G15: =G7/G11 -> 403.84997 | H15: =H7/H11 -> 431.90521 | I15: =I7/I11 -> 618.028 | J15: =J7/J11 -> 775.69908 | K15: =K7/K11 -> 458.84729
B16: [10] | C16: Of which: debt | D16: =(D8+D9)/D12 -> 178.51748 | E16: =(E8+E9)/E12 -> 224.1302 | F16: =(F8+F9)/F12 -> 278.69177 | G16: =(G8+G9)/G12 -> 453.90208 | H16: =(H8+H9)/H12 -> 479.50534 | I16: =(I8+I9)/I12 -> 716.45897 | J16: =(J8+J9)/J12 -> 858.05978 | K16: =(K8+K9)/K12 -> 793.85871
C18: Consistency checks
B19: [11] | C19: Bank assets (CPIS) | D19: 50.817 | E19: 55.19447 | F19: 62.365886 | G19: 57.986295 | H19: 72.30212 | I19: 82.194 | J19: 90.008 | K19: 50.055
B20: [12] | C20: Of which: equities | D20: =D19-D21 -> 0 | E20: =E19-E21 -> 5.068664 | F20: =F19-F21 -> 5.28211 | G20: =G19-G21 -> 2.01508 | H20: =H19-H21 -> 1.81427 | I20: =I19-I21 -> 1.995 | J20: =J19-J21 -> 2.313 | K20: =K19-K21 -> 0.617
B21: [13] | C21: Of which: debt | D21: 50.817 | E21: 50.125806 | F21: 57.083776 | G21: 55.971215 | H21: 70.48785 | I21: 80.199 | J21: 87.695 | K21: 49.438
B22: [14] | C22: Fund assets (CIMA) | D22: n.a. | E22: n.a. | F22: n.a. | G22: n.a. | H22: 768.2512 | I22: 1234.236 | J22: 1707.6144 | K22: 1215.9485
B23: [15] | C23: Of which: equities | D23: n.a. | E23: n.a. | F23: n.a. | G23: n.a. | H23: 607.99138 | I23: 951.72791 | J23: 1187.7842 | K23: 824.88971
B24: [16] | C24: Of which: debt | D24: n.a. | E24: n.a. | F24: n.a. | G24: n.a. | H24: 160.25983 | I24: 282.50813 | J24: 519.83025 | K24: 391.05882
B25: [17] | C25: Banks + Funds (CPIS + CIMA) | D25: n.a. | E25: n.a. | F25: n.a. | G25: n.a. | H25: =H22+H19 -> 840.55332 | I25: =I22+I19 -> 1316.43 | J25: =J22+J19 -> 1797.6224 | K25: =K22+K19 -> 1266.0035
B27: [18] | C27: Liabilities | D27: =D28+D32 -> 677.87753 | E27: =E28+E32 -> 811.14539 | F27: =F28+F32 -> 1050.0305 | G27: =G28+G32 -> 1395.8052 | H27: =H28+H32 -> 1503.5473 | I27: =I28+I32 -> 2012.3156 | J27: =J28+J32 -> 2662.3876 | K27: =K28+K32 -> 2180.6228
B28: [19] | C28: Debt | D28: =MAX(D29,D30) -> 389.262 | E28: =MAX(E29,E30) -> 451.832 | F28: =MAX(F29,F30) -> 529.0553 | G28: =MAX(G29,G30) -> 672.9417 | H28: =MAX(H29,H30) -> 735.4636 | I28: =MAX(I29,I30) -> 946.7028 | J28: =MAX(J29,J30) -> 1177.133 | K28: =MAX(K29,K30) -> 1135.314
B29: [20] | C29: International debt (BIS) | D29: 389.262 | E29: 451.832 | F29: 493.026 | G29: 520.792 | H29: 535.516 | I29: 869.233 | J29: 1177.133 | K29: 1135.314
B30: [21] | C30: Creditor derived debt liabilities | D30: ='Table A11'!D31 -> 327.0328 | E30: ='Table A11'!E31 -> 429.8192 | F30: ='Table A11'!F31 -> 529.0553 | G30: ='Table A11'!G31 -> 672.9417 | H30: ='Table A11'!H31 -> 735.4636 | I30: ='Table A11'!I31 -> 946.7028 | J30: ='Table A11'!J31 -> 1118.502 | K30: ='Table A11'!K31 -> 894.1449
B31: [22] | C31: Equities | D31: =MAX(D32+D33,D34) -> 319.11253 | E31: =MAX(E32+E33,E34) -> 386.27653 | F31: =MAX(F32+F33,F34) -> 561.1922 | G31: =MAX(G32+G33,G34) -> 783.76227 | H31: =MAX(H32+H33,H34) -> 856.52873 | I31: =MAX(I32+I33,I34) -> 1195.0448 | J31: =MAX(J32+J33,J34) -> 1669.3956 | K31: =MAX(K32+K33,K34) -> 1105.9018
B32: [23] | C32: Mutual fund shares (CIMA, est.) | D32: =E32*D14/E14 -> 288.61553 | E32: =F32*E14/F14 -> 359.31339 | F32: =G32*F14/G14 -> 520.9752 | G32: =H32*G14/H14 -> 722.86348 | H32: 768.08373 | I32: 1065.6128 | J32: 1485.2546 | K32: 1045.3088
B33: [24] | C33: U.S. equities on non-fund sector (TIC) | D33: 30.497 | E33: 26.963148 | F33: 40.217 | G33: 60.898792 | H33: 88.445 | I33: 129.432 | J33: 184.141 | K33: 60.593
B34: [25] | C34: Creditor-derived equity liabilities | D34: ='Table A10'!D42 -> 116.6535 | E34: ='Table A10'!E42 -> 134.3438 | F34: ='Table A10'!F42 -> 214.687 | G34: ='Table A10'!G42 -> 307.1049 | H34: ='Table A10'!H42 -> 393.6525 | I34: ='Table A10'!I42 -> 635.7456 | J34: ='Table A10'!J42 -> 871.5224 | K34: ='Table A10'!K42 -> 506.3736
B36: [26] | C36: Net portfolio position | D36: =D14-D27 -> -335.40544 | E36: =E14-E27 -> -384.783 | F36: =F14-F27 -> -431.83971 | G36: =G14-G27 -> -538.05312 | H36: =H14-H27 -> -592.13678 | I36: =I14-I27 -> -677.82868 | J36: =J14-J27 -> -1028.6288 | K36: =K14-K27 -> -927.91683
B37: [27] | C37: Equity | D37: =D15-D32 -> -124.66092 | E37: =E15-E32 -> -157.0812 | F37: =F15-F32 -> -181.47617 | G37: =G15-G32 -> -319.0135 | H37: =H15-H32 -> -336.17853 | I37: =I15-I32 -> -447.58485 | J37: =J15-J32 -> -709.55554 | K37: =K15-K32 -> -586.46154
B38: [28] | C38: Debt | D38: =D16-D28 -> -210.74452 | E38: =E16-E28 -> -227.7018 | F38: =F16-F28 -> -250.36353 | G38: =G16-G28 -> -219.03962 | H38: =H16-H28 -> -255.95826 | I38: =I16-I28 -> -230.24383 | J38: =J16-J28 -> -319.07322 | K38: =K16-K28 -> -341.45529

Sheet Table A7
B2: Table A7: China' Cross-Border Securities Assets (bn of USD)
D4: 2001 | E4: 2002 | F4: 2003 | G4: 2004 | H4: 2005 | I4: 2006 | J4: 2007 | K4: 2008
C5: Public assets
B6: [1] | C6: Memo: total reserve minus gold | D6: 215.605 | E6: 291.128 | F6: 408.151 | G6: 614.5 | H6: 821.514 | I6: 1068.49 | J6: 1530.28 | K6: 1949.26
B7: [2] | C7: Foreign exchange reserves | D7: 212.165 | E7: 286.407 | F7: 403.251 | G7: 609.932 | H7: 818.872 | I7: 1066.34 | J7: 1528.25 | K7: 1946.03
B8: [3] | C8: Foreign portfolio reserves (85% of exchange res.) | D8: =0.85*D7 -> 180.34025 | E8: =0.85*E7 -> 243.44595 | F8: =0.85*F7 -> 342.76335 | G8: =0.85*G7 -> 518.4422 | H8: =0.85*H7 -> 696.0412 | I8: =0.85*I7 -> 906.389 | J8: =0.85*J7 -> 1299.0125 | K8: =0.85*K7 -> 1654.1255
B9: [4] | C9: Of which: equities | D9: 4.3428278 | E9: 2.8582829 | F9: 2.6290851 | G9: 3.1629463 | H9: 3.4282846 | I9: 16.305992 | J9: 83.373269 | K9: 73.915427
B10: [5] | C10: Of which: debt | D10: 175.99742 | E10: 240.58767 | F10: 340.13426 | G10: 515.27925 | H10: 692.61292 | I10: 890.08301 | J10: 1215.6392 | K10: 1580.2101
C12: Private assets
B13: [6] | C13: External Wealth of Nations II, August 2009 | D13: =D14+D15 -> 7.636 | E13: =E14+E15 -> 5.61 | F13: =F14+F15 -> 4.83 | G13: =G14+G15 -> 97.706 | H13: =H14+H15 -> 122.91851 | I13: =I14+I15 -> 272.64949 | J13: =J14+J15 -> 290.25765 | K13: n.a.
B14: [7] | C14: Of which: equities | D14: 7.636 | E14: 5.61 | F14: 4.83 | G14: 5.678 | H14: 6.1790839 | I14: 8.924904 | J14: 25.280064 | K14: n.a.
B15: [8] | C15: Of which: debt | D15: 0 | E15: 0 | F15: 0 | G15: 92.028 | H15: 116.73943 | I15: 263.72459 | J15: 264.97759 | K15: n.a.
B16: [9] | C16: International Investment Position | D16: n.a. | E16: n.a. | F16: n.a. | G16: =G17+G18 -> 92.028 | H16: =H17+H18 -> 116.739 | I16: =I17+I18 -> 265.179 | J16: =J17+J18 -> 284.6206 | K16: =K17+K18 -> 251.8802
B17: [10] | C17: Of which: equities | D17: n.a. | E17: n.a. | F17: n.a. | G17: 0 | H17: 0 | I17: 1.454 | J17: 19.6426 | K17: 20.7602
B18: [11] | C18: Of which: debt | D18: n.a. | E18: n.a. | F18: n.a. | G18: 92.028 | H18: 116.739 | I18: 263.725 | J18: 264.978 | K18: 231.12
B19: [12] | C19: Prefered estimate | D19: =D21+D20 -> 33.43735 | E19: =E21+E20 -> 46.777998 | F19: =F21+F20 -> 64.482567 | G19: =G21+G20 -> 92.827783 | H19: =H21+H20 -> 117.68496 | I19: =I21+I20 -> 267.81133 | J19: =J21+J20 -> 285.84096 | K19: =K21+K20 -> 251.8802
