Workbook
Name B_SEULS_NOVIEUX: #REF!
Name B_SEULS_NOVIEUX: #REF!
Name B_SEULS_NOVIEUX: #REF!
Name B_SEULS_NOVIEUX: #REF!
Name column_head: #REF!
Name column_head: #REF!
Name column_head: #REF!
Name column_head: #REF!
Name column_headings: #REF!
Name column_headings: #REF!
Name column_headings: #REF!
Name column_headings: #REF!
Name column_headings: #REF!
Name column_numbers: #REF!
Name column_numbers: #REF!
Name column_numbers: #REF!
Name column_numbers: #REF!
Name column_numbers: #REF!
Name d: #REF!
Name data: #REF!
Name data: #REF!
Name data: #REF!
Name data: #REF!
Name data: #REF!
Name data2: #REF!
Name data2: #REF!
Name data2: #REF!
Name data2: #REF!
Name e: #REF!
Name ea_flux: #REF!
Name ea_flux: #REF!
Name ea_flux: #REF!
Name ea_flux: #REF!
Name ea_flux: #REF!
Name Equilibre: #REF!
Name Equilibre: #REF!
Name Equilibre: #REF!
Name Equilibre: #REF!
Name Equilibre: #REF!
Name f: #REF!
Name fig4b: #REF!
Name fig4b: #REF!
Name fig4b: #REF!
Name fig4b: #REF!
Name footnotes: #REF!
Name footnotes: #REF!
Name footnotes: #REF!
Name footnotes: #REF!
Name footnotes: #REF!
Name footnotes2: #REF!
Name footnotes2: #REF!
Name footnotes2: #REF!
Name footnotes2: #REF!
Name gg: #REF!
Name head: #REF!
Name name: #REF!
Name name2: #REF!
Name name3: #REF!
Name name4: #REF!
Name nb: #REF!

Sheet Data-Fig1
B2: Securities in custody in Swiss banks | C2: Of which: foreign securities belonging to foreigners | D2: Of which: Swiss securities belonging to foreigners, undeclared | E2: Of which: foreign securities wrongly attributed to Switzerland | F2: Fraction of securities in custody in Switzerland held offshore by foreigners | G2: Fiduciary deposits | H2: Total offshore wealth in Switzerland | I2: Share belonging to Europeans | J2: European fortunes in Switzerland | K2: Fraction of Europe's financial wealth held in Switzerland | L2: Europe's wealth in all tax havens | M2: Memo: Europe national income | N2: (Memo: UK + France + Germany national income) | O2: Memo: Europe net financial wealth/national income | P2: Memo: Europe's net financial wealth
A3: 1910 | B3: 0.98433483 | F3: 0.5 | G3: 0 | H3: =G3+F3*B3 -> 0.49216742 | I3: 1 | J3: =I3*H3 -> 0.49216742 | K3: =J3/(P3+J3) -> 0.0040371224 | L3: =K3 -> 0.0040371224 | M3: =M4*N3/N4 -> 68.743347 | N3: 37.320339 | O3: 1.7662551 | P3: =M3*O3 -> 121.41829
A4: 1920 | B4: 2.6424385 | F4: 0.5 | G4: 0 | H4: =G4+F4*B4 -> 1.3212192 | I4: 0.95 | J4: =I4*H4 -> 1.2551583 | K4: =J4/(P4+J4) -> 0.013715282 | L4: =K4 -> 0.013715282 | M4: =M5*N4/N5 -> 79.308659 | N4: 43.056182 | O4: 1.1380869 | P4: =M4*O4 -> 90.260149
A5: 1930 | B5: 5.4221974 | F5: 0.6 | G5: 0 | H5: =G5+F5*B5 -> 3.2533184 | I5: 0.95 | J5: =I5*H5 -> 3.0906525 | K5: =J5/(P5+J5) -> 0.021873087 | L5: =K5 -> 0.021873087 | M5: =M6*N5/N6 -> 109.70096 | N5: 59.555977 | O5: 1.2598675 | P5: =M5*O5 -> 138.20867
A6: 1940 | B6: 5.3914571 | F6: 0.6 | G6: 0 | H6: =G6+F6*B6 -> 3.2348742 | I6: 0.95 | J6: =I6*H6 -> 3.0731305 | K6: =J6/(P6+J6) -> 0.016456326 | L6: =K6 -> 0.016456326 | M6: =M7*N6/N7 -> 168.09424 | N6: 91.257325 | O6: 1.0926698 | P6: =M6*O6 -> 183.6715
A7: 1950 | B7: 10.153801 | F7: =F$14 -> 0.39527154 | G7: 0.067139495 | H7: =G7+F7*B7 -> 4.0806479 | I7: 0.95 | J7: =I7*H7 -> 3.8766155 | K7: =J7/(P7+J7) -> 0.019907963 | L7: =K7 -> 0.019907963 | M7: =M8*N7/N8 -> 248.79232 | N7: 135.06781 | O7: 0.76710677 | P7: =M7*O7 -> 190.85027
A8: 1960 | B8: 35.747344 | F8: =F$14 -> 0.39527154 | G8: 2.0409204 | H8: =G8+F8*B8 -> 16.170828 | I8: 0.9 | J8: =I8*H8 -> 14.553745 | K8: =J8/(P8+J8) -> 0.031770214 | L8: =K8 -> 0.031770214 | M8: =M9*N8/N9 -> 512.33676 | N8: 278.14447 | O8: 0.8657202 | P8: =M8*O8 -> 443.54028
A9: 1970 | B9: 172.92128 | F9: =F$14 -> 0.39527154 | G9: 25.359544 | H9: =G9+F9*B9 -> 93.710406 | I9: 0.75 | J9: =I9*H9 -> 70.282805 | K9: =J9/(P9+J9) -> 0.045471193 | L9: =K9 -> 0.045471193 | M9: =M10*N9/N10 -> 1608.728 | N9: 873.36849 | O9: 0.91710523 | P9: =M9*O9 -> 1475.3728
A10: 1980 | B10: 575.09997 | F10: =F$14 -> 0.39527154 | G10: 134.26863 | H10: =G10+F10*B10 -> 361.58929 | I10: 0.6 | J10: =I10*H10 -> 216.95357 | K10: =J10/(P10+J10) -> 0.055363674 | L10: =L9+(L$14-L$9)/5 -> 0.056119979 | M10: 3500.2016 | N10: 1900.2379 | O10: 1.0575806 | P10: =M10*O10 -> 3701.7454
A11: 1990 | B11: 1488.6753 | F11: 0.44 | G11: 288.50349 | H11: =G11+F11*B11 -> 943.52063 | I11: 0.6 | J11: =I11*H11 -> 566.11238 | K11: =J11/(P11+J11) -> 0.054864763 | L11: =L10+(L$14-L$9)/5 -> 0.066768765 | M11: 7242.2766 | N11: 4074.2314 | O11: 1.3465671 | P11: =M11*O11 -> 9752.2112
A12: 2000 | B12: 3258.902 | C12: 1305.773 | D12: 124.31399 | E12: 0 | F12: =(C12+D12+E12)/B12 -> 0.43882479 | G12: 407.11989 | H12: =G12+F12*B12 -> 1837.2069 | I12: 0.6 | J12: =I12*H12 -> 1102.3241 | K12: =J12/(P12+J12) -> 0.058807266 | L12: =L11+(L$14-L$9)/5 -> 0.077417552 | M12: 11305.141 | N12: 6006.3561 | O12: 1.5605615 | P12: =M12*O12 -> 17642.368
A13: 2010 | B13: 4768.6797 | C13: 1765.1029 | D13: 77 | E13: 100 | F13: =(C13+D13+E13)/B13 -> 0.40726219 | G13: 269.08862 | H13: =G13+F13*B13 -> 2211.1916 | I13: 0.6 | J13: =I13*H13 -> 1326.7149 | K13: =J13/(P13+J13) -> 0.056981403 | L13: =L12+(L$14-L$9)/5 -> 0.088066338 | M13: 14364.581 | N13: 7123.7848 | O13: 1.5285222 | P13: =M13*O13 -> 21956.582
A14: 2013 | B14: 5245.6449 | C14: 1896.4541 | D14: 77 | E14: 100 | F14: =(C14+D14+E14)/B14 -> 0.39527154 | G14: 213.06184 | H14: =G14+E14+D14+C14 -> 2286.516 | I14: 0.6 | J14: =I14*H14 -> 1371.9096 | K14: =J14/(P14+J14) -> 0.060299856 | L14: ='Tab1'!C5 -> 0.098715125 | M14: 14311.368 | O14: 1.4938857 | P14: =M14*O14 -> 21379.548
A15: 2013 (euros) | B15: =B14/1.3 -> 4035.1115 | C15: =C14/1.3 -> 1458.8109 | D15: =D14/1.3 -> 59.230769 | E15: =E14/1.3 -> 76.923077 | G15: =G14/1.3 -> 163.89373 | H15: =H14/1.3 -> 1758.8585 | J15: =J14/1.3 -> 1055.3151 | M15: =M14/1.3 -> 11008.745 | P15: =P14/1.3 -> 16445.806
A17: Notes: All figures in current billion US$. 1910 is the average of 1910-1919, 1920 the average of 1920-1929... and 2012 the average of 2012-12. Swiss data for 2013 are as at the end of May, and based on the July 2013 Monthly bulletin of economic statistic. Sources: Securities in custody in Swiss banks and fiduciary deposits: See detailed computations & explanations in "SwissBanks20c.xlsx" and the Appendix of the book. Europe net financial wealth / national income 1910: 30% of the average 1910-1919 private wealth-national income ratio of the UK, Germany and France, as reported in Piketty-Zucman (2014, Table A5). 1920-1980: 40% of the European private wealth-income ratio in Piketty-Zucman (2014, Table A8) . 1990-2013: Eurostat (EU 27 data. Series start in 1995 and I assume the same yearly growth rate over 1990-1995 as in 1995-1996, consistent with UK, French and German data). Europe's national income 1980-2012: Eurostat data (EU27. Convereted to US$ using year-average exchange rates); 2013: 2012 national income in euros times 1.3 (memo: euro/dollar exchange rate as of May 2013: 1.304); 1910-1970: based on the evolution of French, UK and German national incomes in current US dollars, as reported in Piketty-Zucman (2014, Table A153)

Sheet Fig2
C2: Swiss bank accounts (2015)
C6: In 2015 banks domiciled in Switzerland manage 2.3 trillion dollars belonging to non-residents. Within this total, 1.3 trillion belong to Europeans. 40% of the wealth managed in Switzerland is placed in mutual funds, principally in Luxembourg.
C11: Who owns Swiss accounts | G11: Investments
C13: Europe: $1,300bn. Of which: Germany: $260bn France: $240bn Italy: $140bn UK: $140bn Spain: $110bn Greece: $80bn Belgium: $70bn Portugal: $40bn Other: $220bn | G13: Luxembourg mutual funds: $750bn
J14: =600/1800*2300 -> 766.66667
E17: Total offshore wealth in Switzerland: $2,300bn
G24: Irish mutual funds: $200bn | J24: =150/1800*2300 -> 191.66667
G27: Global equities (US, etc.) : $500bn
J28: =400/1800*2300 -> 511.11111
C29: Gulf countries: $230bn
C32: Asia: $230bn
G34: Global bonds: $600bn
C35: Latin America: $220bn | J35: =450/1800*2300 -> 575
C38: Africa: $150bn
C40: USA ($80bn) and Canda ($40bn) | G40: Deposits, other: $250bn | J40: =200/1800*2300 -> 255.55556
C42: Russia: $70bn
C47: =70+80+40+150+220+230+230+1300 -> 2320 | G47: =250+600+500+200+750 -> 2300

Sheet DataFig2
H2: Fiduciary deposits official SNB data "Banks in Switzerland" 2013
B3: US$ billion | C3: % of total | D3: Tax revenue losses | H3: 2008-2013 | I3: 2013 | J3: 2012 | K3: 2011 | L3: 2010 | M3: 2009 | N3: 2008
A4: Europe | B4: =ROUND(C4*B$24,-2) -> 1300 | C4: 0.56 | D4: =SUM(D5:D16) -> 38.443665 | H4: =AVERAGE(I4:N4) -> 17427.221 | I4: 8980.0675 | J4: 8933.883 | K4: 14220.774 | L4: 15565.085 | M4: 19608.091 | N4: 37255.425
A5: Germany | B5: =ROUND(B$4*H5/H$4,-1) -> 260 | C5: =B5/B$24 -> 0.11304348 | D5: ='Data-Fig4_Tab1'!B6*(1-'Data-Fig4_Tab1'!H6)*('Data-Fig4_Tab1'!O$3*'Data-Fig4_Tab1'!J6+'Data-Fig4_Tab1'!P$3*'Data-Fig4_Tab1'!K6+'Data-Fig4_Tab1'!L6) -> 6.26496 | H5: =AVERAGE(I5:N5) -> 3421.8635 | I5: 1514.205 | J5: 1733.569 | K5: 2663.028 | L5: 2624.386 | M5: 4133.239 | N5: 7862.754
A6: France | B6: =ROUND(B$4*H6/H$4,-1) -> 240 | C6: =B6/B$24 -> 0.10434783 | D6: ='Data-Fig4_Tab1'!B7*(1-'Data-Fig4_Tab1'!H7)*('Data-Fig4_Tab1'!O$3*'Data-Fig4_Tab1'!J7+'Data-Fig4_Tab1'!P$3*'Data-Fig4_Tab1'!K7+'Data-Fig4_Tab1'!L7) -> 12.2304 | H6: =AVERAGE(I6:N6) -> 3188.6757 | I6: 1641.261 | J6: 1659.261 | K6: 2573.71 | L6: 2868.622 | M6: 3794.505 | N6: 6594.695
A7: Italy | B7: =ROUND(B$4*H7/H$4,-1) -> 140 | C7: =B7/B$24 -> 0.060869565 | D7: ='Data-Fig4_Tab1'!B8*(1-'Data-Fig4_Tab1'!H8)*('Data-Fig4_Tab1'!O$3*'Data-Fig4_Tab1'!J8+'Data-Fig4_Tab1'!P$3*'Data-Fig4_Tab1'!K8+'Data-Fig4_Tab1'!L8) -> 1.9264 | H7: =AVERAGE(I7:N7) -> 1920.62 | I7: 452.882 | J7: 575.783 | K7: 1148.678 | L7: 1275.503 | M7: 2004.648 | N7: 6066.226
A8: UK | B8: =ROUND(B$4*H8/H$4,-1) -> 140 | C8: =B8/B$24 -> 0.060869565 | D8: ='Data-Fig4_Tab1'!B9*(1-'Data-Fig4_Tab1'!H9)*('Data-Fig4_Tab1'!O$3*'Data-Fig4_Tab1'!J9+'Data-Fig4_Tab1'!P$3*'Data-Fig4_Tab1'!K9+'Data-Fig4_Tab1'!L9) -> 4.08576 | H8: =AVERAGE(I8:N8) -> 1886.997 | I8: 962.3365 | J8: 1010.675 | K8: 1527.744 | L8: 1884.5928 | M8: 2272.2328 | N8: 3664.401
A9: Spain | B9: =ROUND(B$4*H9/H$4,-1) -> 110 | C9: =B9/B$24 -> 0.047826087 | D9: ='Data-Fig4_Tab1'!B10*(1-'Data-Fig4_Tab1'!H10)*('Data-Fig4_Tab1'!O$3*'Data-Fig4_Tab1'!J10+'Data-Fig4_Tab1'!P$3*'Data-Fig4_Tab1'!K10+'Data-Fig4_Tab1'!L10) -> 4.9984 | H9: =AVERAGE(I9:N9) -> 1437.3898 | I9: 666.732 | J9: 758.642 | K9: 1227.543 | L9: 1202.054 | M9: 1604.115 | N9: 3165.253
A10: Greece | B10: =ROUND(B$4*H10/H$4,-1) -> 80 | C10: =B10/B$24 -> 0.034782609 | D10: ='Data-Fig4_Tab1'!B11*(1-'Data-Fig4_Tab1'!H11)*('Data-Fig4_Tab1'!O$3*'Data-Fig4_Tab1'!J11+'Data-Fig4_Tab1'!P$3*'Data-Fig4_Tab1'!K11+'Data-Fig4_Tab1'!L11) -> 0.896 | H10: =AVERAGE(I10:N10) -> 1046.0657 | I10: 658.205 | J10: 859.097 | K10: 1158.381 | L10: 1308.538 | M10: 934.844 | N10: 1357.329
A11: Belgium | B11: =ROUND(B$4*H11/H$4,-1) -> 70 | C11: =B11/B$24 -> 0.030434783 | D11: ='Data-Fig4_Tab1'!B12*(1-'Data-Fig4_Tab1'!H12)*('Data-Fig4_Tab1'!O$3*'Data-Fig4_Tab1'!J12+'Data-Fig4_Tab1'!P$3*'Data-Fig4_Tab1'!K12+'Data-Fig4_Tab1'!L12) -> 1.624 | H11: =AVERAGE(I11:N11) -> 940.79683 | I11: 298.885 | J11: 420.985 | K11: 624.186 | L11: 692.988 | M11: 1197.333 | N11: 2410.404
A12: Portugal | B12: =ROUND(B$4*H12/H$4,-1) -> 40 | C12: =B12/B$24 -> 0.017391304 | D12: ='Data-Fig4_Tab1'!B13*(1-'Data-Fig4_Tab1'!H13)*('Data-Fig4_Tab1'!O$3*'Data-Fig4_Tab1'!J13+'Data-Fig4_Tab1'!P$3*'Data-Fig4_Tab1'!K13+'Data-Fig4_Tab1'!L13) -> 0.7168 | H12: =AVERAGE(I12:N12) -> 589.43333 | I12: 1065.29 | J12: 299.055 | K12: 485.327 | L12: 343.271 | M12: 436.653 | N12: 907.004
A13: Poland | B13: =ROUND(B$4*H13/H$4,-1) -> 20 | C13: =B13/B$24 -> 0.0086956522 | D13: ='Data-Fig4_Tab1'!B14*(1-'Data-Fig4_Tab1'!H14)*('Data-Fig4_Tab1'!O$3*'Data-Fig4_Tab1'!J14+'Data-Fig4_Tab1'!P$3*'Data-Fig4_Tab1'!K14+'Data-Fig4_Tab1'!L14) -> 0.2576 | H13: =AVERAGE(I13:N13) -> 209.23317 | I13: 143.562 | J13: 207.272 | K13: 190.661 | L13: 195.089 | M13: 206.914 | N13: 311.901
A14: Sweden | B14: =ROUND(B$4*H14/H$4,-1) -> 20 | C14: =B14/B$24 -> 0.0086956522 | D14: ='Data-Fig4_Tab1'!B15*(1-'Data-Fig4_Tab1'!H15)*('Data-Fig4_Tab1'!O$3*'Data-Fig4_Tab1'!J15+'Data-Fig4_Tab1'!P$3*'Data-Fig4_Tab1'!K15+'Data-Fig4_Tab1'!L15) -> 0.384 | H14: =AVERAGE(I14:N14) -> 230.32867 | I14: 105.161 | J14: 179.598 | K14: 195.389 | L14: 217.956 | M14: 180.987 | N14: 502.881
A15: Norway | B15: =ROUND(B$4*H15/H$4,-1) -> 10 | C15: =B15/B$24 -> 0.0043478261 | D15: ='Data-Fig4_Tab1'!B16*(1-'Data-Fig4_Tab1'!H16)*('Data-Fig4_Tab1'!O$3*'Data-Fig4_Tab1'!J16+'Data-Fig4_Tab1'!P$3*'Data-Fig4_Tab1'!K16+'Data-Fig4_Tab1'!L16) -> 0.3152 | H15: =AVERAGE(I15:N15) -> 95.467167 | I15: 50.685 | J15: 58.908 | K15: 65.48 | L15: 93.711 | M15: 137.815 | N15: 166.204
A16: Other | B16: =ROUND(B$4*H16/H$4,-1) -> 180 | C16: =B16/B$24 -> 0.07826087 | D16: ='Data-Fig4_Tab1'!B17*(1-'Data-Fig4_Tab1'!H17)*('Data-Fig4_Tab1'!O$3*'Data-Fig4_Tab1'!J17+'Data-Fig4_Tab1'!P$3*'Data-Fig4_Tab1'!K17+'Data-Fig4_Tab1'!L17) -> 4.7441455 | H16: =AVERAGE(I16:N16) -> 2460.35 | I16: =I4-SUM(I5:I15) -> 1420.863 | J16: =J4-SUM(J5:J15) -> 1171.038 | K16: =K4-SUM(K5:K15) -> 2360.647 | L16: =L4-SUM(L5:L15) -> 2858.374 | M16: =M4-SUM(M5:M15) -> 2704.805 | N16: =N4-SUM(N5:N15) -> 4246.373
A17: Gulf countries | B17: =ROUND(C17*B$24,-1) -> 230 | C17: 0.1 | D17: ='Data-Fig4_Tab1'!B18*(1-'Data-Fig4_Tab1'!H18)*('Data-Fig4_Tab1'!O$3*'Data-Fig4_Tab1'!J18+'Data-Fig4_Tab1'!P$3*'Data-Fig4_Tab1'!K18+'Data-Fig4_Tab1'!L18) -> 0
A18: Asia | B18: =ROUND(C18*B$24,-1) -> 230 | C18: 0.1 | D18: ='Data-Fig4_Tab1'!B19*(1-'Data-Fig4_Tab1'!H19)*('Data-Fig4_Tab1'!O$3*'Data-Fig4_Tab1'!J19+'Data-Fig4_Tab1'!P$3*'Data-Fig4_Tab1'!K19+'Data-Fig4_Tab1'!L19) -> 6.072
A19: Latin America | B19: =ROUND(C19*B$24,-1) -> 220 | C19: =11.5%-2% -> 0.095 | D19: ='Data-Fig4_Tab1'!B20*(1-'Data-Fig4_Tab1'!H20)*('Data-Fig4_Tab1'!O$3*'Data-Fig4_Tab1'!J20+'Data-Fig4_Tab1'!P$3*'Data-Fig4_Tab1'!K20+'Data-Fig4_Tab1'!L20) -> 6.2928
A20: Africa | B20: =ROUND(C20*B$24,-1) -> 150 | C20: 0.065 | D20: ='Data-Fig4_Tab1'!B21*(1-'Data-Fig4_Tab1'!H21)*('Data-Fig4_Tab1'!O$3*'Data-Fig4_Tab1'!J21+'Data-Fig4_Tab1'!P$3*'Data-Fig4_Tab1'!K21+'Data-Fig4_Tab1'!L21) -> 4.3056
A21: United States | B21: =ROUND(C21*B$24,-1) -> 80 | C21: =0.05*2/3 -> 0.033333333 | H21: =AVERAGE(I21:N21) -> 2680.9245 | I21: 1226.013 | J21: 1411.906 | K21: 1411.906 | L21: 2990.565 | M21: 3097.081 | N21: 5948.076
A22: Canada | B22: =ROUND(C22*B$24,-1) -> 40 | C22: =0.05*1/3 -> 0.016666667 | H22: =AVERAGE(I22:N22) -> 1170.9032 | I22: 754.843 | J22: 695.81 | K22: 921.935 | L22: 1473.971 | M22: 1356.444 | N22: 1822.416
A23: Russia | B23: =ROUND(C23*B$24,-1) -> 70 | C23: 0.03 | D23: ='Data-Fig4_Tab1'!B24*(1-'Data-Fig4_Tab1'!H24)*('Data-Fig4_Tab1'!O$3*'Data-Fig4_Tab1'!J24+'Data-Fig4_Tab1'!P$3*'Data-Fig4_Tab1'!K24+'Data-Fig4_Tab1'!L24) -> 0.39744 | H23: =AVERAGE(I23:N23) -> 3246.8855 | I23: 2534.479 | J23: 2508.164 | K23: 2802.473 | L23: 2843.699 | M23: 3518.252 | N23: 5274.246
A24: Total | B24: 2300 | C24: =C4+SUM(C17:C23) -> 1 | D24: =D4+SUM(D17:D23) -> 55.511505 | G24: Total excl. Liechtenstein | H24: =AVERAGE(I24:N24) -> 153998.21 | I24: 91448.792 | J24: 98892.075 | K24: 129209.07 | L24: 145181.39 | M24: 179027.08 | N24: 280230.87
A25: Of which: through shell companies | B25: =ROUND(C25*B24,-2) -> 1400 | C25: 0.6 | G25: Tax havens excl. Liechtenstein | H25: =AVERAGE(I25:N25) -> 84962.761 | I25: 50734.891 | J25: 54886.173 | K25: 68461.426 | L25: 81942.425 | M25: 100525.7 | N25: 153225.96
G26: Liechtenstein | H26: =AVERAGE(I26:N26) -> 27088.187 | I26: 15215.918 | J26: 17761.015 | K26: 21553.273 | L26: 26140.689 | M26: 33818.559 | N26: 48039.669
G27: Total incl. Liechtenstein | H27: =AVERAGE(I27:N27) -> 181086.4 | I27: =I24+I26 -> 106664.71 | J27: =J24+J26 -> 116653.09 | K27: =K24+K26 -> 150762.34 | L27: =L24+L26 -> 171322.07 | M27: =M24+M26 -> 212845.64 | N27: =N24+N26 -> 328270.54
G28: Tax havens incl. Liechtenstein | H28: =AVERAGE(I28:N28) -> 112050.95 | I28: =I26+I25 -> 65950.808 | J28: =J26+J25 -> 72647.188 | K28: =K26+K25 -> 90014.699 | L28: =L26+L25 -> 108083.11 | M28: =M26+M25 -> 134344.26 | N28: =N26+N25 -> 201265.62
G29: Share shell | H29: =AVERAGE(I29:N29) -> 0.61888229 | I29: =I28/I27 -> 0.61830017 | J29: =J28/J27 -> 0.62276265 | K29: =K28/K27 -> 0.59706354 | L29: =L28/L27 -> 0.63087676 | M29: =M28/M27 -> 0.63118162 | N29: =N28/N27 -> 0.61310901
G30: Share Europe | H30: =AVERAGE(I30:N30) -> 0.091927799 | I30: =I4/I27 -> 0.084189678 | J30: =J4/J27 -> 0.076585053 | K30: =K4/K27 -> 0.094325768 | L30: =L4/L27 -> 0.090852769 | M30: =M4/M27 -> 0.092123525 | N30: =N4/N27 -> 0.11349
A32: Notes: Continental shares are from Zucman (2013, Table A26, line for 2004, the last year which is note contaminated by the saving directive), with the following changes:
A33: Russia (3%) is isolated from Asia (which thus decreases from 13% to 10%).
A34: Latin America is reduced by 2 points and Gulf countries increased by 2 points to account for recent evolution
A35: Non-oil Middle East countries (about 2%) are merged with Africa (which thus increases from 5% to 7%)
A36: North America is split into USA (2/3 of North America based on average share of US in 2008-2013 North American fiduciary deposits) and Canada (1/3)
A37: Within Europe, shares are obtained from 2008-2013 average shares of individual European countries in European-owned fiduciary deposits
A38: UK deposits are divided by 4 to account for sham corporations; this is very uncertain

Sheet Fig3
B3: Financial wealth in tax havens (2014)
B7: In 2014, on a global scale households on average owned 8% of their financial wealth through bank accounts in tax havens. One-third of the world’s offshore wealth was in Switzerland
B12: World financial wealth: 95.5 trillion $ (100%) | D12: Held onshore (in the U.S., Japan, France…) : 87.9 trillion $ (92 %)
F22: Around 30% of offshore wealth is in Switzerland: 2.3 trillion $
D26: Held offshore (in tax havens throughout the world): 7.6 trillion $ (8%)
F28: 70% is in tax havens other than Switzerland (Singapore, Cayman islands…): 5.3 trillion $

Sheet Data-Fig3
F2: bn euros | H2: bn US$
C3: World income | F3: =ROUND(H3/E$13,-3) -> 62000 | H3: =0.85*80000 -> 68000
C4: World financial wealth | F4: =ROUND(H4/E$13,-3) -> 87000 | G4: =F4/F3 -> 1.4032258 | H4: =H3*0.3*4.4/(1-0.06) -> 95489.362
C5: Of which: held offshore | F5: =ROUND(H5/E$13,-2) -> 6900 | G5: 0.08 | H5: ='Tab1'!B13 -> 7600
C6: Of which: held offshore in Switzerland | F6: =ROUND(H6/E$13,-2) -> 2100 | G6: =F6/F5 -> 0.30434783 | H6: =DataFig2!B24 -> 2300
C7: Of which: held in havens other than Sw. | F7: =ROUND(H7/E$13,-2) -> 4800 | H7: =H5-H6 -> 5300
C9: European financial wealth | F9: =ROUND(H9/E$13,-2) -> 21800 | H9: =H10+'Data-Fig1'!P14 -> 23979.548
C10: Offshore financial wealth of Europeans | F10: =ROUND(H10/E$13,-2) -> 2400 | G10: =F10/F9 -> 0.11009174 | H10: ='Tab1'!B5 -> 2600
D13: 1 euro = | E13: 1.1 | F13: dollars

Sheet Fig4
B3: The global cost of offshore tax evasion (2014)
B7: En 2013, la fraude permise par le secret bancaire a coûé 130 milliards d'euros aux États du monde entier.
B12: Global household wealth in tax havens: $7,600bn (100%)
J13: =5800*1.3 -> 7540
J14: =J13*0.2 -> 1508
B18: Of which declared: $1,500bn (20%) | D18: Of which undeclared : $6,100bn (80%)
D24: Yearly tax revenue losses due to offshore tax evasion $190bn
J26: =130*1.3 -> 169
D30: Of which income tax (interest, dividends): $125bn | F30: Of which inheritance tax: $55bn | H30: Of which wealth tax: $10bn
J37: =80*1.3 -> 104
J38: =45*1.3 -> 58.5
J39: =5*1.3 -> 6.5

Sheet Tab1
B4: Offshore wealth ($ bn) | C4: Share of financial wealth held offshore | D4: Tax revenue loss ($ bn) | J4: Net onshore financial wealth (bn$) | K4: Gross financial wealth per adult ($) | L4: Debt per adult ($) | M4: Number of adults (mn)
A5: Europe | B5: =ROUND('Data-Fig4_Tab1'!F5,-2) -> 2600 | C5: ='Data-Fig4_Tab1'!G5*0.08*J13/(J5+'Data-Fig4_Tab1'!G5*0.08*J13) -> 0.098715125 | D5: =ROUND('Data-Fig4_Tab1'!N5*D$13,0) -> 78 | J5: 23980 | M5: =583.373-M11 -> 473.008
A6: USA | B6: =ROUND('Data-Fig4_Tab1'!F22,-2) -> 1200 | C6: ='Data-Fig4_Tab1'!G22*0.08*J13/(J6+'Data-Fig4_Tab1'!G22*0.08*J13) -> 0.035031864 | D6: =ROUND('Data-Fig4_Tab1'!N22*D$13,0) -> 35 | J6: 33296.92 | M6: 239
A7: Asia | B7: =ROUND('Data-Fig4_Tab1'!F19,-2) -> 1300 | C7: ='Data-Fig4_Tab1'!G19*0.08*J13/(J7+'Data-Fig4_Tab1'!G19*0.08*J13) -> 0.041725283 | D7: =ROUND('Data-Fig4_Tab1'!N19*D$13,0) -> 34 | J7: =(K7-L7)*M7/1000 -> 29779.118 | K7: =(26019*1107+10752*998+700*768)/M7 -> 14065.178 | L7: =(7827*1107+1403*998+296*768)/M7 -> 3612.5502 | M7: =1107+998+768-M12 -> 2848.96
A8: Latin America | B8: =ROUND('Data-Fig4_Tab1'!F20,-2) -> 700 | C8: ='Data-Fig4_Tab1'!G20*0.08*J13/(J8+'Data-Fig4_Tab1'!G20*0.08*J13) -> 0.2164944 | D8: =ROUND('Data-Fig4_Tab1'!N20*D$13,0) -> 21 | J8: =(K8-L8)*M8/1000 -> 2626.419 | K8: 10036 | L8: 3353 | M8: 393
A9: Africa | B9: =ROUND('Data-Fig4_Tab1'!F21,-2) -> 500 | C9: ='Data-Fig4_Tab1'!G21*0.08*J13/(J9+'Data-Fig4_Tab1'!G21*0.08*J13) -> 0.29896217 | D9: =ROUND('Data-Fig4_Tab1'!N21*D$13,0) -> 14 | J9: =(K9-L9)*M9/1000 -> 1164.35 | K9: 2629 | L9: 512 | M9: 550
A10: Canada | B10: =ROUND('Data-Fig4_Tab1'!F23,-2) -> 300 | C10: ='Data-Fig4_Tab1'!G23*0.08*J13/(J10+'Data-Fig4_Tab1'!G23*0.08*J13) -> 0.092044985 | D10: =ROUND('Data-Fig4_Tab1'!N23*D$13,0) -> 6 | J10: =(K10-L10)*M10/1000 -> 2814.966 | K10: 166409 | L10: 62151 | M10: 27
A11: Russia | B11: =ROUND('Data-Fig4_Tab1'!F24,-2) -> 200 | C11: ='Data-Fig4_Tab1'!G24*0.08*J13/(J11+'Data-Fig4_Tab1'!G24*0.08*J13) -> 0.51802588 | D11: =ROUND('Data-Fig4_Tab1'!N24*D$13,0) -> 1 | J11: =(K11-L11)*M11/1000 -> 213.22518 | K11: 4484 | L11: 2552 | M11: 110.365
A12: Gulf countries | B12: 800 | C12: ='Data-Fig4_Tab1'!G18*0.08*J13/(J12+'Data-Fig4_Tab1'!G18*0.08*J13) -> 0.5680577 | D12: =ROUND('Data-Fig4_Tab1'!N18*D$13,0) -> 0 | J12: =(K12-L12)*M12/1000 -> 580.86908 | K12: =(16.694*19652+1.278*99415+2.291*64918+3.777*83377)/M12 -> 38218.175 | L12: =(16.694*5862+1.278*18652+2.291*23631+3.777*42907)/M12 -> 14055.568 | M12: =16.694+1.278+2.291+3.777 -> 24.04
A13: Total | B13: =ROUND(0.08*J13,-2) -> 7600 | C13: =B13/J13 -> 0.079590018 | D13: =ROUND(0.08*J13*'Data-Fig4_Tab1'!M25/'Data-Fig4_Tab1'!F25,-1) -> 190 | J13: ='Data-Fig3'!H4 -> 95489.362
J15: USA: Saez-Zucman, 2014 (= Flow of Funds); Europe: Zucman, 2013 (= Eurostat); total = onshore + offshore total in Zucman 2013; rest: Credit Suisse (2013)

Sheet Data-Fig4_Tab1
O2: r (nominal) | P2: m x mu
O3: 0.08 | P3: 0.03
B4: Offshore wealth in Switzerland | C4: (%) | D4: Offshore wealth in other tax havens | E4: (%) | F4: Offshore wealth in all tax havens | G4: (%) | H4: % of offshore wealth declared | I4: Undeclared offshore wealth | J4: Dividend income tax rate (OECD) | K4: Top marginal inheritance/estate tax rate | L4: Welath tax rate | M4: Total tax revenue losses | N4: (%) | O4: Income tax revenue losses | P4: Inheritance/Estate tax revenue losses | Q4: Wealth tax revenue losses | R4: Income + wealth tax revenue losses | S4: Income + wealth tax revenue losses (% undeclared income)
A5: Europe | B5: =C5*DataFig2!B$24 -> 1288 | C5: =DataFig2!C4 -> 0.56 | D5: =E5*D$25 -> 1325 | E5: 0.25 | F5: =B5+D5 -> 2613 | G5: =F5/F$25 -> 0.34381579 | H5: 0.2 | I5: =(1-H5)*F5 -> 2090.4 | M5: =O5+P5+Q5 -> 77.991691 | N5: =M5/M$25 -> 0.41180646 | O5: =SUM(O6:O17) -> 48.196999 | P5: =SUM(P6:P17) -> 19.310232 | Q5: =SUM(Q6:Q17) -> 10.48446 | R5: =(O5+Q5) -> 58.681459 | S5: =R5/(O$3*I5) -> 0.3508985
A6: Germany | B6: =C6*DataFig2!B$24 -> 260 | C6: =DataFig2!C5 -> 0.11304348 | D6: =E6*D$25 -> 267.46894 | E6: =E$5*C6/C$5 -> 0.050465839 | F6: =B6+D6 -> 527.46894 | G6: =F6/F$25 -> 0.069403808 | H6: 0.2 | I6: =(1-H6)*F6 -> 421.97516 | J6: 0.264 | K6: 0.3 | L6: 0 | M6: =O6+P6+Q6 -> 12.709892 | N6: =M6/M$25 -> 0.067109912 | O6: =O$3*J6*I6 -> 8.9121153 | P6: =I6*P$3*K6 -> 3.7977764 | Q6: =L6*I6 -> 0 | R6: =(O6+Q6) -> 8.9121153 | S6: =R6/(O$3*I6) -> 0.264
A7: France | B7: =C7*DataFig2!B$24 -> 240 | C7: =DataFig2!C6 -> 0.10434783 | D7: =E7*D$25 -> 246.89441 | E7: =E$5*C7/C$5 -> 0.046583851 | F7: =B7+D7 -> 486.89441 | G7: =F7/F$25 -> 0.064065054 | H7: 0.2 | I7: =(1-H7)*F7 -> 389.51553 | J7: 0.44 | K7: 0.45 | L7: 0.015 | M7: =O7+P7+Q7 -> 24.812139 | N7: =M7/M$25 -> 0.13101138 | O7: =O$3*J7*I7 -> 13.710947 | P7: =I7*P$3*K7 -> 5.2584596 | Q7: =L7*I7 -> 5.8427329 | R7: =(O7+Q7) -> 19.55368 | S7: =R7/(O$3*I7) -> 0.6275
A8: Italy | B8: =C8*DataFig2!B$24 -> 140 | C8: =DataFig2!C7 -> 0.060869565 | D8: =E8*D$25 -> 144.02174 | E8: =E$5*C8/C$5 -> 0.027173913 | F8: =B8+D8 -> 284.02174 | G8: =F8/F$25 -> 0.037371281 | H8: 0.2 | I8: =(1-H8)*F8 -> 227.21739 | J8: 0.2 | K8: 0.04 | L8: 0 | M8: =O8+P8+Q8 -> 3.9081391 | N8: =M8/M$25 -> 0.020635492 | O8: =O$3*J8*I8 -> 3.6354783 | P8: =I8*P$3*K8 -> 0.27266087 | Q8: =L8*I8 -> 0 | R8: =(O8+Q8) -> 3.6354783 | S8: =R8/(O$3*I8) -> 0.2
A9: UK | B9: =C9*DataFig2!B$24 -> 140 | C9: =DataFig2!C8 -> 0.060869565 | D9: =E9*D$25 -> 144.02174 | E9: =E$5*C9/C$5 -> 0.027173913 | F9: =B9+D9 -> 284.02174 | G9: =F9/F$25 -> 0.037371281 | H9: 0.2 | I9: =(1-H9)*F9 -> 227.21739 | J9: 0.306 | K9: 0.4 | L9: 0 | M9: =O9+P9+Q9 -> 8.2888904 | N9: =M9/M$25 -> 0.043766439 | O9: =O$3*J9*I9 -> 5.5622817 | P9: =I9*P$3*K9 -> 2.7266087 | Q9: =L9*I9 -> 0 | R9: =(O9+Q9) -> 5.5622817 | S9: =R9/(O$3*I9) -> 0.306
A10: Spain | B10: =C10*DataFig2!B$24 -> 110 | C10: =DataFig2!C9 -> 0.047826087 | D10: =E10*D$25 -> 113.15994 | E10: =E$5*C10/C$5 -> 0.021350932 | F10: =B10+D10 -> 223.15994 | G10: =F10/F$25 -> 0.02936315 | H10: 0.2 | I10: =(1-H10)*F10 -> 178.52795 | J10: 0.27 | K10: 0.34 | L10: 0.025 | M10: =O10+P10+Q10 -> 10.140388 | N10: =M10/M$25 -> 0.05354259 | O10: =O$3*J10*I10 -> 3.8562037 | P10: =I10*P$3*K10 -> 1.8209851 | Q10: =L10*I10 -> 4.4631988 | R10: =(O10+Q10) -> 8.3194025 | S10: =R10/(O$3*I10) -> 0.5825
A11: Greece | B11: =C11*DataFig2!B$24 -> 80 | C11: =DataFig2!C10 -> 0.034782609 | D11: =E11*D$25 -> 82.298137 | E11: =E$5*C11/C$5 -> 0.01552795 | F11: =B11+D11 -> 162.29814 | G11: =F11/F$25 -> 0.021355018 | H11: 0.2 | I11: =(1-H11)*F11 -> 129.83851 | J11: 0.1 | K11: 0.2 | L11: 0 | M11: =O11+P11+Q11 -> 1.8177391 | N11: =M11/M$25 -> 0.0095979034 | O11: =O$3*J11*I11 -> 1.0387081 | P11: =I11*P$3*K11 -> 0.77903106 | Q11: =L11*I11 -> 0 | R11: =(O11+Q11) -> 1.0387081 | S11: =R11/(O$3*I11) -> 0.1
A12: Belgium | B12: =C12*DataFig2!B$24 -> 70 | C12: =DataFig2!C11 -> 0.030434783 | D12: =E12*D$25 -> 72.01087 | E12: =E$5*C12/C$5 -> 0.013586957 | F12: =B12+D12 -> 142.01087 | G12: =F12/F$25 -> 0.018685641 | H12: 0.2 | I12: =(1-H12)*F12 -> 113.6087 | J12: 0.25 | K12: 0.3 | L12: 0 | M12: =O12+P12+Q12 -> 3.2946522 | N12: =M12/M$25 -> 0.0173962 | O12: =O$3*J12*I12 -> 2.2721739 | P12: =I12*P$3*K12 -> 1.0224783 | Q12: =L12*I12 -> 0 | R12: =(O12+Q12) -> 2.2721739 | S12: =R12/(O$3*I12) -> 0.25
A13: Portugal | B13: =C13*DataFig2!B$24 -> 40 | C13: =DataFig2!C12 -> 0.017391304 | D13: =E13*D$25 -> 41.149068 | E13: =E$5*C13/C$5 -> 0.0077639752 | F13: =B13+D13 -> 81.149068 | G13: =F13/F$25 -> 0.010677509 | H13: 0.2 | I13: =(1-H13)*F13 -> 64.919255 | J13: 0.28 | K13: 0 | L13: 0 | M13: =O13+P13+Q13 -> 1.4541913 | N13: =M13/M$25 -> 0.0076783227 | O13: =O$3*J13*I13 -> 1.4541913 | P13: =I13*P$3*K13 -> 0 | Q13: =L13*I13 -> 0 | R13: =(O13+Q13) -> 1.4541913 | S13: =R13/(O$3*I13) -> 0.28
A14: Poland | B14: =C14*DataFig2!B$24 -> 20 | C14: =DataFig2!C13 -> 0.0086956522 | D14: =E14*D$25 -> 20.574534 | E14: =E$5*C14/C$5 -> 0.0038819876 | F14: =B14+D14 -> 40.574534 | G14: =F14/F$25 -> 0.0053387545 | H14: 0.2 | I14: =(1-H14)*F14 -> 32.459627 | J14: 0.19 | K14: 0.03 | L14: 0 | M14: =O14+P14+Q14 -> 0.5226 | N14: =M14/M$25 -> 0.0027593972 | O14: =O$3*J14*I14 -> 0.49338634 | P14: =I14*P$3*K14 -> 0.029213665 | Q14: =L14*I14 -> 0 | R14: =(O14+Q14) -> 0.49338634 | S14: =R14/(O$3*I14) -> 0.19
A15: Sweden | B15: =C15*DataFig2!B$24 -> 20 | C15: =DataFig2!C14 -> 0.0086956522 | D15: =E15*D$25 -> 20.574534 | E15: =E$5*C15/C$5 -> 0.0038819876 | F15: =B15+D15 -> 40.574534 | G15: =F15/F$25 -> 0.0053387545 | H15: 0.2 | I15: =(1-H15)*F15 -> 32.459627 | J15: 0.3 | K15: 0 | L15: 0 | M15: =O15+P15+Q15 -> 0.77903106 | N15: =M15/M$25 -> 0.0041133872 | O15: =O$3*J15*I15 -> 0.77903106 | P15: =I15*P$3*K15 -> 0 | Q15: =L15*I15 -> 0 | R15: =(O15+Q15) -> 0.77903106 | S15: =R15/(O$3*I15) -> 0.3
A16: Norway | B16: =C16*DataFig2!B$24 -> 10 | C16: =DataFig2!C15 -> 0.0043478261 | D16: =E16*D$25 -> 10.287267 | E16: =E$5*C16/C$5 -> 0.0019409938 | F16: =B16+D16 -> 20.287267 | G16: =F16/F$25 -> 0.0026693772 | H16: 0.2 | I16: =(1-H16)*F16 -> 16.229814 | J16: 0.28 | K16: 0.2 | L16: 0.011 | M16: =O16+P16+Q16 -> 0.63945466 | N16: =M16/M$25 -> 0.0033764053 | O16: =O$3*J16*I16 -> 0.36354783 | P16: =I16*P$3*K16 -> 0.097378882 | Q16: =L16*I16 -> 0.17852795 | R16: =(O16+Q16) -> 0.54207578 | S16: =R16/(O$3*I16) -> 0.4175
A17: Other | B17: =C17*DataFig2!B$24 -> 180 | C17: =DataFig2!C16 -> 0.07826087 | D17: =E17*D$25 -> 185.17081 | E17: =E$5*C17/C$5 -> 0.034937888 | F17: =B17+D17 -> 365.17081 | G17: =F17/F$25 -> 0.04804879 | H17: 0.2 | I17: =(1-H17)*F17 -> 292.13665 | J17: =AVERAGE(J6:J16) -> 0.26181818 | K17: 0.4 | L17: 0 | M17: =O17+P17+Q17 -> 9.6245746 | N17: =M17/M$25 -> 0.050819029 | O17: =O$3*J17*I17 -> 6.1189348 | P17: =I17*P$3*K17 -> 3.5056398 | Q17: =L17*I17 -> 0 | R17: =(O17+Q17) -> 6.1189348 | S17: =R17/(O$3*I17) -> 0.26181818
A18: Gulf countries | B18: =C18*DataFig2!B$24 -> 230 | C18: =DataFig2!C17 -> 0.1 | D18: =E18*D$25 -> 530 | E18: =C18 -> 0.1 | F18: =B18+D18 -> 760 | G18: =F18/F$25 -> 0.1 | H18: 0.2 | I18: =(1-H18)*F18 -> 608 | J18: 0 | K18: 0 | L18: 0 | M18: =O18+P18+Q18 -> 0 | N18: =M18/M$25 -> 0 | O18: =O$3*J18*I18 -> 0 | P18: =I18*P$3*K18 -> 0 | Q18: =L18*I18 -> 0 | R18: =(O18+Q18) -> 0
A19: Asia | B19: =C19*DataFig2!B$24 -> 230 | C19: =DataFig2!C18 -> 0.1 | D19: =E19*D$25 -> 1060 | E19: 0.2 | F19: =B19+D19 -> 1290 | G19: =F19/F$25 -> 0.16973684 | H19: 0.2 | I19: =(1-H19)*F19 -> 1032 | J19: 0.3 | K19: 0.3 | L19: 0 | M19: =O19+P19+Q19 -> 34.056 | N19: =M19/M$25 -> 0.17982019 | O19: =O$3*J19*I19 -> 24.768 | P19: =I19*P$3*K19 -> 9.288 | Q19: =L19*I19 -> 0 | R19: =(O19+Q19) -> 24.768 | S19: =R19/(O$3*I19) -> 0.3
A20: Latin America | B20: =C20*DataFig2!B$24 -> 218.5 | C20: =DataFig2!C19 -> 0.095 | D20: =E20*D$25 -> 503.5 | E20: =C20 -> 0.095 | F20: =B20+D20 -> 722 | G20: =F20/F$25 -> 0.095 | H20: 0.2 | I20: =(1-H20)*F20 -> 577.6 | J20: 0.3 | K20: 0.4 | L20: 0 | M20: =O20+P20+Q20 -> 20.7936 | N20: =M20/M$25 -> 0.10979296 | O20: =O$3*J20*I20 -> 13.8624 | P20: =I20*P$3*K20 -> 6.9312 | Q20: =L20*I20 -> 0 | R20: =(O20+Q20) -> 13.8624 | S20: =R20/(O$3*I20) -> 0.3
A21: Africa | B21: =C21*DataFig2!B$24 -> 149.5 | C21: =DataFig2!C20 -> 0.065 | D21: =E21*D$25 -> 344.5 | E21: =C21 -> 0.065 | F21: =B21+D21 -> 494 | G21: =F21/F$25 -> 0.065 | H21: 0.2 | I21: =(1-H21)*F21 -> 395.2 | J21: 0.3 | K21: 0.4 | L21: 0 | M21: =O21+P21+Q21 -> 14.2272 | N21: =M21/M$25 -> 0.075121501 | O21: =O$3*J21*I21 -> 9.4848 | P21: =I21*P$3*K21 -> 4.7424 | Q21: =L21*I21 -> 0 | R21: =(O21+Q21) -> 9.4848 | S21: =R21/(O$3*I21) -> 0.3
A22: United States | B22: =C22*DataFig2!B$24 -> 76.666667 | C22: =DataFig2!C21 -> 0.033333333 | D22: =F22-B22 -> 1125.9382 | E22: =D22/D$25 -> 0.21244117 | F22: =G22*F$25 -> 1202.6049 | G22: 0.15823748 | H22: 0.2 | I22: =(1-H22)*F22 -> 962.0839 | J22: 0.303 | K22: 0.4 | L22: 0 | M22: =O22+P22+Q22 -> 34.86592 | N22: =M22/M$25 -> 0.18409668 | O22: =O$3*J22*I22 -> 23.320914 | P22: =I22*P$3*K22 -> 11.545007 | Q22: =L22*I22 -> 0 | R22: =(O22+Q22) -> 23.320914 | S22: =R22/(O$3*I22) -> 0.303
A23: Canada | B23: =C23*DataFig2!B$24 -> 38.333333 | C23: =DataFig2!C22 -> 0.016666667 | D23: =F23-B23 -> 245.57463 | E23: =D23/D$25 -> 0.046334835 | F23: =G23*F$25 -> 283.90796 | G23: 0.03735631 | H23: 0.2 | I23: =(1-H23)*F23 -> 227.12637 | J23: 0.338 | K23: 0 | L23: 0 | M23: =O23+P23+Q23 -> 6.141497 | N23: =M23/M$25 -> 0.032427917 | O23: =O$3*J23*I23 -> 6.141497 | P23: =I23*P$3*K23 -> 0 | Q23: =L23*I23 -> 0 | R23: =(O23+Q23) -> 6.141497 | S23: =R23/(O$3*I23) -> 0.338
A24: Russia | B24: =C24*DataFig2!B$24 -> 69 | C24: =DataFig2!C23 -> 0.03 | D24: =E24*D$25 -> 159 | E24: =C24 -> 0.03 | F24: =B24+D24 -> 228 | G24: =F24/F$25 -> 0.03 | H24: 0.2 | I24: =(1-H24)*F24 -> 182.4 | J24: 0.09 | K24: 0 | L24: 0 | M24: =O24+P24+Q24 -> 1.31328 | N24: =M24/M$25 -> 0.0069342924 | O24: =O$3*J24*I24 -> 1.31328 | P24: =I24*P$3*K24 -> 0 | Q24: =L24*I24 -> 0 | R24: =(O24+Q24) -> 1.31328 | S24: =R24/(O$3*I24) -> 0.09
A25: Total | B25: =DataFig2!B24 -> 2300 | C25: =B25/B$25 -> 1 | D25: =7600-'Data-Fig4_Tab1'!B25 -> 5300 | E25: =SUM(E18:E24)+E5 -> 0.99877601 | F25: =B25+D25 -> 7600 | G25: =F25/F$25 -> 1 | H25: 0.2 | I25: =SUM(I18:I24)+I5 -> 6074.8103 | M25: =O25+P25+Q25 -> 189.38919 | N25: =M25/M$25 -> 1 | O25: =SUM(O18:O24)+O5 -> 127.08789 | P25: =SUM(P18:P24)+P5 -> 51.816839 | Q25: =SUM(Q18:Q24)+Q5 -> 10.48446 | R25: =(O25+Q25) -> 137.57235 | S25: =R25/(O$3*I25) -> 0.28307952
P27: =P25/(P$3*I25) -> 0.28432624
A29: Source: Zucman 2014 JEP. I make 4 changes: (i) based on the latest Fiduciary Statistics data from the 2013 edition of "Banks in Switzerland", share of Swiss offshore wealth assigned to the US is increased by 1 point and that assigned to Canada decreased by 1 point. I am adjusting the non-Swiss offshore wealth of US and Canada accordingly so that total offshore wealth matches the figures given in the JEP paper. (ii) Fraction of offshore wealth declared is set at 20% for all countries, based on latest AFC STD data (see update to Johannesen Zucman 2014 and December 2014 update to JEP appendix: http://gabriel-zucman.eu/files/Zucman2014JEPAppendix.pdf); (iii) Nominal rate of return on offshore assets changed to 8% based on latest values of 10-years returns on Venduard diversified funds (see link in cell O3). (iv) Wealth tax rates are updated and improved (e.g., I now take int account the new wealth tax in Spain).

Sheet Data-Fig5
B1: Tax havens | C1: Europe | D1: Middle East | E1: Latin and South America | F1: Asia | G1: Africa | H1: North America | I1: (Memo: Caribbean)
A2: 1976 | B2: 0.3142881 | C2: 0.383268 | D2: 0.14346484 | E2: 0.052798399 | F2: 0.032321295 | G2: 0.044874468 | H2: 0.028984903 | I2: 0
A3: 1977 | B3: 0.3306751 | C3: 0.40017874 | D3: 0.11759247 | E3: 0.051491819 | F3: 0.03279252 | G3: 0.045957652 | H3: 0.021311701 | I3: 0
A4: 1978 | B4: 0.34341296 | C4: 0.35723073 | D4: 0.14106709 | E4: 0.052724932 | F4: 0.027120584 | G4: 0.055070805 | H4: 0.023372908 | I4: 0
A5: 1979 | B5: 0.31128158 | C5: 0.38623512 | D5: 0.14029815 | E5: 0.053976037 | F5: 0.026691447 | G5: 0.055261181 | H5: 0.026256475 | I5: 0
A6: 1980 | B6: 0.27521767 | C6: 0.41674304 | D6: 0.14493355 | E6: 0.058067934 | F6: 0.029255929 | G6: 0.049891167 | H6: 0.025890709 | I6: 0
A7: 1981 | B7: 0.25785437 | C7: 0.44283856 | D7: 0.12873097 | E7: 0.072365618 | F7: 0.027762205 | G7: 0.04418855 | H7: 0.026259727 | I7: 0
A8: 1982 | B8: 0.26838302 | C8: 0.39270133 | D8: 0.17117342 | E8: 0.065783494 | F8: 0.03096028 | G8: 0.044446464 | H8: 0.026551991 | I8: 0
A9: 1983 | B9: 0.28996576 | C9: 0.35507826 | D9: 0.18609925 | E9: 0.062466649 | F9: 0.035096496 | G9: 0.043000711 | H9: 0.028292867 | I9: 0
A10: 1984 | B10: 0.31450227 | C10: 0.30732502 | D10: 0.20626049 | E10: 0.063228154 | F10: 0.044309969 | G10: 0.031724651 | H10: 0.032378042 | I10: 0.00027140861
A11: 1985 | B11: 0.3211251 | C11: 0.30381032 | D11: 0.20444627 | E11: 0.060325632 | F11: 0.048060994 | G11: 0.030612608 | H11: 0.031414219 | I11: 0.00020485598
A12: 1986 | B12: 0.33761827 | C12: 0.30588823 | D12: 0.18129725 | E12: 0.062041619 | F12: 0.04906591 | G12: 0.030271281 | H12: 0.033599832 | I12: 0.00021760505
A13: 1987 | B13: 0.34666633 | C13: 0.31276382 | D13: 0.16543127 | E13: 0.062554035 | F13: 0.046553171 | G13: 0.029541525 | H13: 0.036292783 | I13: 0.00019707064
... A34: 2008 | B34: 0.61401599 | C34: 0.15679436 | D34: 0.078365778 | E34: 0.045494606 | F34: 0.062434711 | G34: 0.017455091 | H34: 0.025014497 | I34: 0.00042496802
A35: 2009 | B35: =DataFig2!M29 -> 0.63118162 | C35: =DataFig2!M30/DataFig2!N30*C34 -> 0.12727508
A36: 2010 | B36: =DataFig2!L29 -> 0.63087676 | C36: =C35*DataFig2!L30/DataFig2!M30 -> 0.12551944
A37: 2011 | B37: =DataFig2!K29 -> 0.59706354 | C37: =C36*DataFig2!K30/DataFig2!L30 -> 0.13031763
A38: 2012 | B38: =DataFig2!J29 -> 0.62276265 | C38: =C37*DataFig2!J30/DataFig2!K30 -> 0.10580759
A39: 2013 | B39: =DataFig2!I29 -> 0.61830017 | C39: =C38*DataFig2!I30/DataFig2!J30 -> 0.11631391
A40: 2014
A41: 2015
B43: Source: Zucman (2013, Appendix Table A25) through to 2008; 2009-2013: update based on SNB's Banks in Switzerland yearly data

Sheet Data-Fig6
B1: Finance | C1: Industry
A2: 1970 | B2: 0.018088811 | C2: 0.45012818
A3: 1971 | B3: 0.041427958 | C3: 0.390531
A4: 1972 | B4: 0.073390782 | C4: 0.36250889
A5: 1973 | B5: 0.063235996 | C5: 0.39211404
A6: 1974 | B6: 0.060347298 | C6: 0.41294522
A7: 1975 | B7: 0.15858149 | C7: 0.27833434
A8: 1976 | B8: 0.1745468 | C8: 0.29064719
A9: 1977 | B9: 0.19524552 | C9: 0.25920675
A10: 1978 | B10: 0.1848296 | C10: 0.26856304
A11: 1979 | B11: 0.14042651 | C11: 0.2828928
A12: 1980 | B12: 0.11177975 | C12: 0.2792505
A13: 1981 | B13: 0.13803883 | C13: 0.26420699
... A45: 2013 | B45: 0.40805417 | C45: 0.077748391

Sheet Fig7
B3: The case for a world financial register
B7: The companies Clearstream, Euroclear, etc. feed the world financial register. Tax authorities can verify that tax-payers indeed declare all the financial securities included in the register
B16: Despository Trust Corporation (USA) | D16: World financial register | F16: U.S. tax authority
B21: Clearstream (Luxembourg) | F21: U.K. tax authority
B26: Euroclear France (France) | F26: French tax authority
B31: Other central securities depositories & other sources | F31: Other tax administrations

Sheet DataFig8-9
A1: (May 2014 JEP comps) | D1: Domestic vs. foreign profits | O1: From IRS to BEA profits | Y1: S corporations | AG1: Corporate tax revenue | AU1: Tax rate computations | BC1: Distributed vs retained profits | BQ1: Decomposition of foreign profits by country | CT1: Decomposition of foreign retained earnings by country | DJ1: Decomposition of USDIA flows (= outflows of both equity & debt + retained earnings) by country | DU1: Decomposition of equity & debt DI outflows (USDIA flows - DI retained) | EP1: Decomposition of DI assets by country | FA1: Returns on USDIA by country (exploratory, not used in JEP)
A2: (Revised August 2014)
B3: Series | C3: National income | D3: Pre-tax corporate profits with IVA and CCAdj (BEA) | E3: (corporate profits % national income) | F3: Equals | G3: Domestic profits | H3: (domestic profits % national income) | I3: Net foreign profits | J3: (net foreign profits % of national income) | K3: (net foreign profits % of BEA profits) | L3: (Foreign profits inflows) | M3: (Foreign profits inflows % NI) | N3: (Foreign profits inflows, % BEA profits) | O3: Pre-tax corporate profits with IVA and CCAdj (BEA) | P3: Equals | Q3: Corporate profits (IRS) | R3: Misreporting on IRS returns | S3: (misreporting % of BEA profits) | T3: Fed profits | U3: IVA and CCAdj | V3: Less: Capital gains | W3: (capital gains % of BEA profits) | X3: Other adjustmetns to IRS data | Y3: Total receipts less total deductions, IRS | Z3: Revisions to IRS "Total Receipts Less Total Deductions", BEA | AA3: (Of which: bad debt expenses) | AB3: (Of which: other) | AC3: S corporations profits included in BEA profits | AD3: Memo: share of S corp profits in BEA profits | AE3: Memo: S corporation dividends included in NIPA corporate dividends | AF3: Memo: S corporation net profits taxed at individual level | AG3: Taxes on corporate income | AH3: (corporate tax % of national income) | AI3: (corporate tax excluding fed profits % of national income) | AJ3: Equals | AK3: Paid to federal gov, net of credits | AL3: Paid to local & state gov | AM3: Paid by domestic corp to foreign gov on income earned abroad | AN3: Paid by Fed | AO3: Memo: credits for foreign taxes paid [more or less = total nonresident income tax paid] | AP3: Memo: Federal corporate tax revenu, OMB, calendar year estimate | AQ3: Memo: foreign taxes paid, accrued, and deemed paid, IRS | AR3: Memo: foreign profits repatriated, IRS | AS3: Memo: foreign profits repatriated, IRS | AT3: After-tax corporate profits / national income | AU3: Staturoy federal corporate tax rate | AV3: Effective tax rate paid to US (fed+local) | AW3: Excluding S corp | AX3: Effective tax rate paid to US (including KG in profits) | AY3: Effective tax rate paid worldwide | AZ3: Excluding S corp | BA3: Effective tax rate IRS | BB3: Effective tax rate IRS after misreporting | BC3: Pre-tax corporate profits with IVA and CCAdj (BEA) | BD3: Equals | BE3: Corporate income taxes | BF3: Distributed earnings | BG3: Retained earnings | BH3: (retained earnings % BEA profits) | BI3: Retained domestic | BJ3: Retained abroad | BK3: (Retained foreign, % of BEA profits) | BL3: (Retained havens, % of BEA profits) | BM3: (Retained havens, % of DI income) | BN3: (check) | BO3: (Retained abroad, % of foreign profits) | BP3: Memo: distributions on US DI = repatriations | BQ3: Foreign profits | BR3: Equals | BS3: Diff geographical coverage btw NIPA and BoP | BT3: PI dividends | BU3: DI (divs+retained) with CCAdj | BV3: CCAdj | BW3: Memo: share of DI in foreign profits | BX3: USDIA without CCAdj | BY3: Ireland | BZ3: Netherlands | CA3: Luxembourg | CB3: Switzerland | CC3: Bermuda & other Caribbean | CD3: Bermuda | CE3: Other Caribbean | CF3: Singapore | CG3: Top 6 havens | CH3: Non havens | CI3: Ireland | CJ3: Netherlands | CK3: Luxembourg | CL3: Switzerland | CM3: Bermuda & other Caribbean | CN3: Bermuda | CO3: Other Caribbean | CP3: Singapore | CQ3: Top 6 havens % of total DI income | CR3: Top 6 havens % of all U.S. corporate profits | CS3: DI without CCAdj | CT3: USDIA without CCAdj | CU3: Equals | CV3: DI distributed | CW3: DI retained | CX3: Ireland | CY3: Netherlands | CZ3: Luxembourg | DA3: Switzerland | DB3: Bermuda & other Caribbean | DC3: Singapore | DD3: Top 6 havens | DE3: In constant $? | DF3: Top 6 havens retained / top 6 heavens profits | DG3: Non havens | DH3: Top 6 havens % of total DI retained | DI3: DI retained/total DI | DJ3: DI outflows | DK3: Ireland | DL3: Netherlands | DM3: Luxembourg | DN3: Switzerland | DO3: Bermuda & other Caribbean | DP3: (Bermuda) | DQ3: Singapore | DR3: Top 6 havens | DS3: Non havens | DT3: Top 6 havens % of total DI outflows | DU3: DI equity & debt ouflows | DV3: (check) | DW3: Ireland | DX3: Netherlands | DY3: Luxembourg | DZ3: Switzerland | EA3: Bermuda & other Caribbean | EB3: Singapore | EC3: Top 6 havens | ED3: Non havens | EE3: Top 6 havens % of total DI outflows | EF3: DI equity outflow | EG3: Ireland | EH3: Netherlands | EI3: Luxembourg | EJ3: Switzerland | EK3: Bermuda & other Caribbean | EL3: Singapore | EM3: Top 6 havens | EN3: Non havens | EO3: Top 6 havens % of total DI equity outflows | EP3: DI assets historical cost | EQ3: Ireland | ER3: Netherlands | ES3: Luxembourg | ET3: Switzerland | EU3: Bermuda & other Caribbean | EV3: (Bermuda) | EW3: Singapore | EX3: Top 6 havens | EY3: Non havens | EZ3: Top 6 havens % of total DI assets | FA3: Historical cost total return | FB3: Ireland | FC3: Netherlands | FD3: Luxembourg | FE3: Switzerland | FF3: Bermuda & other Caribbean | FG3: (Bermuda) | FH3: Singapore | FI3: Top 6 havens | FJ3: Non havens | FK3: Non-havens, pre-foreign corp tax (assuming havens =0 tax) | FL3: Yield (historical cost) | FM3: Ireland | FN3: Netherlands | FO3: Luxembourg | FP3: Switzerland | FQ3: Bermuda & other Caribbean | FR3: (Bermuda) | FS3: Singapore | FT3: Top 6 havens | FU3: Non havens | FV3: Royalties etc.
B4: Notes | D4: Net of interest payments | G4: Gross of income taxes (both US taxes and the small amount of taxes paid by domestic businesses to foreign governments) | I4: US profits abroad minus foreign profits in the US. Includes DI + dividend portion of PI (but not retained earnings on PI). Is net of nonresident corporate income tax. | L4: US profits abroad. No data prior to 1948 assume same evolution as net foreign profits | R4: The IRS audit consists of three steps. First, the IRS audits a small sampling of corporations and recommends how much, if any, additional tax liability is owed. Next, the corporations can appeal those recommendations. Finally, a resolution between the corporation and the IRS is reached, and the corporation pays the IRS. The methodology for the misreporting adjustment is to capture only the amount of tax actually collected (see the section “Taxes on Corporate Income”), raise it to a universe total, and then convert it from a tax-liability measure to a profits measure. | X4: Mosty equal to bad debt expense in recent years | Y4: From SOI S corp stats Table 1.-, S-Corporation, All Returns: Total Receipts and Deductions | Z4: Definitional adjustment: To restate profits of small business corporations to reflect the income and expenses that are passed to shareholders rather than reported by the corporation. See http://www.bea.gov/national/pdf/chapter13.pdf. Only known in 2010 (-21bn), assume constant fraction of IRS profits before. | AA4: Part of what corporations can deduct from their IRS profits, but not deduced for NIPA profit computations. Data here from SOI S corp Table 1 | AC4: 1995-on: see formula; before: based on evolution of net S corp income reported by individual taxpayers | AE4: Bigger than 100% of S corporation net profits because of S corp losses (which do not generate negative dividends) | AF4: From Saez-Zucman 2014 total | AG4: Excludes nonresident income tax paid by affiliates | AL4: 2013 data point from Table 1: http://www.census.gov/govs/qtax/ | AN4: Alsmot all Fed profits are treated as corporate taxes by BEA (this is a bit weird; might make more sense for BEA to record that as dividend) | AO4: NB: (i) sometimes foreign tax rates are bigger than US tax rate so no credit; (ii) credits triggered only when repatriation; (iii) since 2007 this is exactly equal to "foreign tax credit claim" from IRS form 1118; before however, this is bigger than IRS 1118 total, with a gap increasing the further one goes back (eg in 1992: total IRS 1118 =21.5bn vs. 25.3bn here), unclear why | AP4: Raw data are fiscal year, here I attempt a calander year conversion. The U.S. federal government's fiscal year begins on 1 October of the previous calendar year and ends on 30 September of the year with which it is numbered. Prior to 1976, the fiscal year began on 1 July and ended on 30 June. | AQ4: From tabulations of IRS form 1118, http://www.irs.gov/uac/SOI-Tax-Stats-Corporate-Foreign-Tax-Credit-Table-1 | AR4: Taxable income (less loss) before adjustments From tabulations of IRS form 1118, http://www.irs.gov/uac/SOI-Tax-Stats-Corporate-Foreign-Tax-Credit-Table-1. Bigger than repatriations from BoP because (i) includes subpart F income; (ii) here is gross of foreign corporate taxes paid (vs. net in BoP) | AS4: Taxable income (less loss) after adjustments From tabulations of IRS form 1118, http://www.irs.gov/uac/SOI-Tax-Stats-Corporate-Foreign-Tax-Credit-Table-1 | AU4: Source Tax Policy Center http://www.taxpolicycenter.org/taxfacts/content/pdf/corporate_historical_bracket.pdf | AV4: Excluding Fed payments | AX4: Excluding Fed payments | AY4: Excluding Fed payments; and assuming that the foreign tax credit equals tax liability on income earned abroad (the convention used in the national accounts), ie in particular that foreign taxes paid on unrepatriated earnings are negligible (consistent with corporate filings, e.g. Microsoft 2014, but would need to be investigated more systematically) | BA4: Does not decline because of growing misreporting | BC4: Net of interest payments | BQ4: PI divs + DI divs & retained. (As always, corporate profits = net of interest payments) | BS4: Puerto Rico etc. | BW4: Note that DI include retained earnings but PI do not | CU4: Unclear where this discrepancy comes from, revisions? | DD4: This is lower than the $2tr one often hears because this is historical cost data; also not all foreign subsidiaries of US firms belong 100% to the US | FA4: What we'd like is market-value total return; pb = not published at country level; plus unclear how to measure MV of Goodle BM?. On the other hand (i) historical cost include some KG (unclear what exactly; also my method to compute KG will include other changes, like data revisions etc.; however not clear why it should benefit havens more than non-havens); (ii) it's useful to have "book values" to detect profit shifting in yieds (ie high yield = BM generates huge profits compared to low book value assets); pb= yield differential havens/non havens does not seem huge and it seems it can be accounted for by the fact that inv flows are post foreign corp taxes | FI4: Positive valuation effect only for havens | FK4: Still positive returns diff after corp tax, entirely due to valuation effect. Why?? | FT4: This differential is what we would expect, because DI profits are net of foreign corporate taxes paid. Ce qu'il faudrait c'est réattribuer les foreign taxes paid pour pouvoir calculer des pre-tax yields = à faire avec BEA data on affiliates
B5: 1929 | C5: 94.2 | D5: 10.8 | E5: =D5/C5 -> 0.11464968 | F5: =D5-(G5+I5) -> 0 | G5: =D5-I5 -> 10.6 | H5: =G5/C5 -> 0.11252654 | I5: 0.2 | J5: =I5/C5 -> 0.0021231423 | K5: =I5/D5 -> 0.018518519 | L5: =I5 -> 0.2 | M5: =L5/C5 -> 0.0021231423 | N5: =L5/D5 -> 0.018518519 | O5: =D5 -> 10.8 | P5: =O5-(Q5+R5+T5+U5+X5-V5) -> 0 | Q5: 11.9 | R5: 0.7 | S5: =R5/D5 -> 0.064814815 | T5: 0 | U5: -0.1 | V5: 0.7 | W5: =V5/D5 -> 0.064814815 | X5: =O5-(Q5+R5+T5+U5-V5) -> -1 | AC5: 0 | AD5: =AC5/D5 -> 0 | AG5: 1.4 | AH5: =AG5/C5 -> 0.014861996 | AI5: =(AG5-AN5)/C5 -> 0.014861996 | AJ5: =AG5-(AK5+AL5+AM5+AN5) -> 0 | AK5: 1.3 | AL5: 0.1 | AM5: 0 | AN5: 0 | AO5: 0 | AT5: =(O5-AG5)/C5 -> 0.099787686 | AU5: 0.11 | BC5: =D5 -> 10.8 | BD5: =BC5-(BE5+BF5+BG5) -> -0.1 | BE5: =AG5 -> 1.4 | BF5: 5.8 | BG5: 3.7 | BI5: 3.7 | BJ5: =BG5-BI5 -> 0 | BK5: =BJ5/D5 -> 0
B6: 1930 | C6: 83.1 | D6: 7.5 | E6: =D6/C6 -> 0.090252708 | F6: =D6-(G6+I6) -> 0 | G6: =D6-I6 -> 7.4 | H6: =G6/C6 -> 0.089049338 | I6: 0.1 | J6: =I6/C6 -> 0.0012033694 | K6: =I6/D6 -> 0.013333333 | L6: =I6 -> 0.1 | M6: =L6/C6 -> 0.0012033694 | N6: =L6/D6 -> 0.013333333 | O6: =D6 -> 7.5 | P6: =O6-(Q6+R6+T6+U6+X6-V6) -> 0 | Q6: 4.6 | R6: 0.6 | S6: =R6/D6 -> 0.08 | T6: 0 | U6: 3 | V6: -0.2 | W6: =V6/D6 -> -0.026666667 | X6: =O6-(Q6+R6+T6+U6-V6) -> -0.9 | AC6: 0 | AD6: =AC6/D6 -> 0 | AG6: 0.8 | AH6: =AG6/C6 -> 0.0096269555 | AI6: =(AG6-AN6)/C6 -> 0.0096269555 | AJ6: =AG6-(AK6+AL6+AM6+AN6) -> -0.1 | AK6: 0.8 | AL6: 0.1 | AM6: 0 | AN6: 0 | AO6: 0 | AT6: =(O6-AG6)/C6 -> 0.080625752 | AU6: 0.12 | BC6: =D6 -> 7.5 | BD6: =BC6-(BE6+BF6+BG6) -> 0 | BE6: =AG6 -> 0.8 | BF6: 5.5 | BG6: 1.2 | BI6: 1.2 | BJ6: =BG6-BI6 -> 0 | BK6: =BJ6/D6 -> 0
B7: 1931 | C7: 67.7 | D7: 3 | E7: =D7/C7 -> 0.044313146 | F7: =D7-(G7+I7) -> 0 | G7: =D7-I7 -> 3 | H7: =G7/C7 -> 0.044313146 | I7: 0 | J7: =I7/C7 -> 0 | K7: =I7/D7 -> 0 | L7: =I7 -> 0 | M7: =L7/C7 -> 0 | N7: =L7/D7 -> 0 | O7: =D7 -> 3 | P7: =O7-(Q7+R7+T7+U7+X7-V7) -> 0 | Q7: -0.8 | R7: 0.4 | S7: =R7/D7 -> 0.13333333 | T7: 0 | U7: 2.4 | V7: -1.3 | W7: =V7/D7 -> -0.43333333 | X7: =O7-(Q7+R7+T7+U7-V7) -> -0.3 | AC7: 0 | AD7: =AC7/D7 -> 0 | AG7: 0.5 | AH7: =AG7/C7 -> 0.0073855244 | AI7: =(AG7-AN7)/C7 -> 0.0073855244 | AJ7: =AG7-(AK7+AL7+AM7+AN7) -> 0 | AK7: 0.4 | AL7: 0.1 | AM7: 0 | AN7: 0 | AO7: 0 | AT7: =(O7-AG7)/C7 -> 0.036927622 | AU7: 0.12 | BC7: =D7 -> 3 | BD7: =BC7-(BE7+BF7+BG7) -> 0 | BE7: =AG7 -> 0.5 | BF7: 4.1 | BG7: -1.6 | BI7: -1.6 | BJ7: =BG7-BI7 -> 0 | BK7: =BJ7/D7 -> 0
B8: 1932 | C8: 51.3 | D8: -0.2 | E8: =D8/C8 -> -0.0038986355 | F8: =D8-(G8+I8) -> 0 | G8: =D8-I8 -> -0.2 | H8: =G8/C8 -> -0.0038986355 | I8: 0 | J8: =I8/C8 -> 0 | K8: =I8/D8 -> 0 | L8: =I8 -> 0 | M8: =L8/C8 -> 0 | N8: =L8/D8 -> 0 | O8: =D8 -> -0.2 | P8: =O8-(Q8+R8+T8+U8+X8-V8) -> 0 | Q8: -3.8 | R8: 0.3 | S8: =R8/D8 -> -1.5 | T8: 0 | U8: 1.1 | V8: -1.6 | W8: =V8/D8 -> 8 | X8: =O8-(Q8+R8+T8+U8-V8) -> 0.6 | AC8: 0 | AD8: =AC8/D8 -> 0 | AG8: 0.4 | AH8: =AG8/C8 -> 0.007797271 | AI8: =(AG8-AN8)/C8 -> 0.007797271 | AJ8: =AG8-(AK8+AL8+AM8+AN8) -> 0 | AK8: 0.3 | AL8: 0.1 | AM8: 0 | AN8: 0 | AO8: 0 | AT8: =(O8-AG8)/C8 -> -0.011695906 | AU8: 0.1375 | BC8: =D8 -> -0.2 | BD8: =BC8-(BE8+BF8+BG8) -> 0 | BE8: =AG8 -> 0.4 | BF8: 2.5 | BG8: -3.1 | BI8: -3.1 | BJ8: =BG8-BI8 -> 0 | BK8: =BJ8/D8 -> 0
B9: 1933 | C9: 49 | D9: -0.2 | E9: =D9/C9 -> -0.0040816327 | F9: =D9-(G9+I9) -> 0 | G9: =D9-I9 -> -0.2 | H9: =G9/C9 -> -0.0040816327 | I9: 0 | J9: =I9/C9 -> 0 | K9: =I9/D9 -> 0 | L9: =L10*I9/I10 -> 0 | M9: =L9/C9 -> 0 | N9: =L9/D9 -> 0 | O9: =D9 -> -0.2 | P9: =O9-(Q9+R9+T9+U9+X9-V9) -> 0 | Q9: -0.9 | R9: 0.4 | S9: =R9/D9 -> -2 | T9: 0 | U9: -2 | V9: -1.4 | W9: =V9/D9 -> 7 | X9: =O9-(Q9+R9+T9+U9-V9) -> 0.9 | AC9: 0 | AD9: =AC9/D9 -> 0 | AG9: 0.5 | AH9: =AG9/C9 -> 0.010204082 | AI9: =(AG9-AN9)/C9 -> 0.010204082 | AJ9: =AG9-(AK9+AL9+AM9+AN9) -> -0.1 | AK9: 0.5 | AL9: 0.1 | AM9: 0 | AN9: 0 | AO9: 0 | AT9: =(O9-AG9)/C9 -> -0.014285714 | AU9: 0.1375 | BC9: =D9 -> -0.2 | BD9: =BC9-(BE9+BF9+BG9) -> 0 | BE9: =AG9 -> 0.5 | BF9: 2 | BG9: -2.7 | BI9: -2.7 | BJ9: =BG9-BI9 -> 0 | BK9: =BJ9/D9 -> 0
B10: 1934 | C10: 58.3 | D10: 2.5 | E10: =D10/C10 -> 0.042881647 | F10: =D10-(G10+I10) -> 0 | G10: =D10-I10 -> 2.4 | H10: =G10/C10 -> 0.041166381 | I10: 0.1 | J10: =I10/C10 -> 0.0017152659 | K10: =I10/D10 -> 0.04 | L10: =L11*I10/I11 -> 0.13076923 | M10: =L10/C10 -> 0.00224304 | N10: =L10/D10 -> 0.052307692 | O10: =D10 -> 2.5 | P10: =O10-(Q10+R10+T10+U10+X10-V10) -> 0 | Q10: 3 | R10: 0.6 | S10: =R10/D10 -> 0.24 | T10: 0 | U10: -0.7 | V10: -0.1 | W10: =V10/D10 -> -0.04 | X10: =O10-(Q10+R10+T10+U10-V10) -> -0.5 | AC10: 0 | AD10: =AC10/D10 -> 0 | AG10: 0.7 | AH10: =AG10/C10 -> 0.012006861 | AI10: =(AG10-AN10)/C10 -> 0.012006861 | AJ10: =AG10-(AK10+AL10+AM10+AN10) -> -0.1 | AK10: 0.7 | AL10: 0.1 | AM10: 0 | AN10: 0 | AO10: 0 | AP10: 0.4465 | AT10: =(O10-AG10)/C10 -> 0.030874786 | AU10: 0.1375 | AV10: =(AK10+AL10)/(G10+L10-T10) -> 0.31610942 | AX10: =(AG10-AN10-AM10)/(G10+L10-T10+V10) -> 0.28797468 | AY10: =(AG10-AN10-AM10+AO10)/(G10+L10-T10+AO10) -> 0.27659574 | AZ10: =(AG10-AN10-AM10+AO10)/(G10+L10-T10+AO10-AC10) -> 0.27659574 | BA10: =(AG10-AN10)/Q10 -> 0.23333333 | BB10: =(AG10-AN10)/(Q10+R10) -> 0.19444444 | BC10: =D10 -> 2.5 | BD10: =BC10-(BE10+BF10+BG10) -> 0 | BE10: =AG10 -> 0.7 | BF10: 2.6 | BG10: -0.8 | BI10: -0.8 | BJ10: =BG10-BI10 -> 0 | BK10: =BJ10/D10 -> 0
B11: 1935 | C11: 66.4 | D11: 4 | E11: =D11/C11 -> 0.060240964 | F11: =D11-(G11+I11) -> 0 | G11: =D11-I11 -> 3.8 | H11: =G11/C11 -> 0.057228916 | I11: 0.2 | J11: =I11/C11 -> 0.0030120482 | K11: =I11/D11 -> 0.05 | L11: =L12*I11/I12 -> 0.26153846 | M11: =L11/C11 -> 0.0039388323 | N11: =L11/D11 -> 0.065384615 | O11: =D11 -> 4 | P11: =O11-(Q11+R11+T11+U11+X11-V11) -> 0 | Q11: 5.4 | R11: 0.5 | S11: =R11/D11 -> 0.125 | T11: 0 | U11: -0.3 | V11: 0.2 | W11: =V11/D11 -> 0.05 | X11: =O11-(Q11+R11+T11+U11-V11) -> -1.4 | AC11: 0 | AD11: =AC11/D11 -> 0 | AG11: 1 | AH11: =AG11/C11 -> 0.015060241 | AI11: =(AG11-AN11)/C11 -> 0.015060241 | AJ11: =AG11-(AK11+AL11+AM11+AN11) -> 0 | AK11: 0.9 | AL11: 0.1 | AM11: 0 | AN11: 0 | AO11: 0 | AP11: 0.624 | AT11: =(O11-AG11)/C11 -> 0.045180723 | AU11: 0.1375 | AV11: =(AK11+AL11)/(G11+L11-T11) -> 0.24621212 | AX11: =(AG11-AN11-AM11)/(G11+L11-T11+V11) -> 0.23465704 | AY11: =(AG11-AN11-AM11+AO11)/(G11+L11-T11+AO11) -> 0.24621212 | AZ11: =(AG11-AN11-AM11+AO11)/(G11+L11-T11+AO11-AC11) -> 0.24621212 | BA11: =(AG11-AN11)/Q11 -> 0.18518519 | BB11: =(AG11-AN11)/(Q11+R11) -> 0.16949153 | BC11: =D11 -> 4 | BD11: =BC11-(BE11+BF11+BG11) -> 0 | BE11: =AG11 -> 1 | BF11: 2.8 | BG11: 0.2 | BH11: =BG11/D11 -> 0.05 | BI11: 0.2 | BJ11: =BG11-BI11 -> 0 | BK11: =BJ11/D11 -> 0
B12: 1936 | C12: 75.2 | D12: 6.2 | E12: =D12/C12 -> 0.082446809 | F12: =D12-(G12+I12) -> 0 | G12: =D12-I12 -> 6.1 | H12: =G12/C12 -> 0.081117021 | I12: 0.1 | J12: =I12/C12 -> 0.0013297872 | K12: =I12/D12 -> 0.016129032 | L12: =L13*I12/I13 -> 0.13076923 | M12: =L12/C12 -> 0.0017389525 | N12: =L12/D12 -> 0.021091811 | O12: =D12 -> 6.2 | P12: =O12-(Q12+R12+T12+U12+X12-V12) -> 0 | Q12: 7.8 | R12: 0.6 | S12: =R12/D12 -> 0.096774194 | T12: 0 | U12: -0.8 | V12: 0.4 | W12: =V12/D12 -> 0.064516129 | X12: =O12-(Q12+R12+T12+U12-V12) -> -1 | AC12: 0 | AD12: =AC12/D12 -> 0 | AG12: 1.4 | AH12: =AG12/C12 -> 0.018617021 | AI12: =(AG12-AN12)/C12 -> 0.018617021 | AJ12: =AG12-(AK12+AL12+AM12+AN12) -> -0.1 | AK12: 1.3 | AL12: 0.2 | AM12: 0 | AN12: 0 | AO12: 0 | AP12: 0.8785 | AT12: =(O12-AG12)/C12 -> 0.063829787 | AU12: 0.15 | AV12: =(AK12+AL12)/(G12+L12-T12) -> 0.24074074 | AX12: =(AG12-AN12-AM12)/(G12+L12-T12+V12) -> 0.21113689 | AY12: =(AG12-AN12-AM12+AO12)/(G12+L12-T12+AO12) -> 0.22469136 | AZ12: =(AG12-AN12-AM12+AO12)/(G12+L12-T12+AO12-AC12) -> 0.22469136 | BA12: =(AG12-AN12)/Q12 -> 0.17948718 | BB12: =(AG12-AN12)/(Q12+R12) -> 0.16666667 | BC12: =D12 -> 6.2 | BD12: =BC12-(BE12+BF12+BG12) -> 0 | BE12: =AG12 -> 1.4 | BF12: 4.5 | BG12: 0.3 | BH12: =BG12/D12 -> 0.048387097 | BI12: 0.3 | BJ12: =BG12-BI12 -> 0 | BK12: =BJ12/D12 -> 0
B13: 1937 | C13: 83.7 | D13: 7.1 | E13: =D13/C13 -> 0.084826762 | F13: =D13-(G13+I13) -> 0 | G13: =D13-I13 -> 6.8 | H13: =G13/C13 -> 0.081242533 | I13: 0.3 | J13: =I13/C13 -> 0.0035842294 | K13: =I13/D13 -> 0.042253521 | L13: =L14*I13/I14 -> 0.39230769 | M13: =L13/C13 -> 0.0046870692 | N13: =L13/D13 -> 0.055254605 | O13: =D13 -> 7.1 | P13: =O13-(Q13+R13+T13+U13+X13-V13) -> 0 | Q13: 7.8 | R13: 0.7 | S13: =R13/D13 -> 0.098591549 | T13: 0 | U13: -0.5 | V13: 0.1 | W13: =V13/D13 -> 0.014084507 | X13: =O13-(Q13+R13+T13+U13-V13) -> -0.8 | AC13: 0 | AD13: =AC13/D13 -> 0 | AG13: 1.5 | AH13: =AG13/C13 -> 0.017921147 | AI13: =(AG13-AN13)/C13 -> 0.017921147 | AJ13: =AG13-(AK13+AL13+AM13+AN13) -> -0.1 | AK13: 1.4 | AL13: 0.2 | AM13: 0 | AN13: 0 | AO13: 0 | AP13: 1.1625 | AT13: =(O13-AG13)/C13 -> 0.066905615 | AU13: 0.15 | AV13: =(AK13+AL13)/(G13+L13-T13) -> 0.22245989 | AX13: =(AG13-AN13-AM13)/(G13+L13-T13+V13) -> 0.2056962 | AY13: =(AG13-AN13-AM13+AO13)/(G13+L13-T13+AO13) -> 0.20855615 | AZ13: =(AG13-AN13-AM13+AO13)/(G13+L13-T13+AO13-AC13) -> 0.20855615 | BA13: =(AG13-AN13)/Q13 -> 0.19230769 | BB13: =(AG13-AN13)/(Q13+R13) -> 0.17647059 | BC13: =D13 -> 7.1 | BD13: =BC13-(BE13+BF13+BG13) -> 0 | BE13: =AG13 -> 1.5 | BF13: 4.7 | BG13: 0.9 | BH13: =BG13/D13 -> 0.12676056 | BI13: 0.7 | BJ13: =BG13-BI13 -> 0.2 | BK13: =BJ13/D13 -> 0.028169014
B14: 1938 | C14: 77.1 | D14: 5 | E14: =D14/C14 -> 0.064850843 | F14: =D14-(G14+I14) -> 0 | G14: =D14-I14 -> 4.7 | H14: =G14/C14 -> 0.060959792 | I14: 0.3 | J14: =I14/C14 -> 0.0038910506 | K14: =I14/D14 -> 0.06 | L14: =L15*I14/I15 -> 0.39230769 | M14: =L14/C14 -> 0.0050882969 | N14: =L14/D14 -> 0.078461538 | O14: =D14 -> 5 | P14: =O14-(Q14+R14+T14+U14+X14-V14) -> 0 | Q14: 4.1 | R14: 0.5 | S14: =R14/D14 -> 0.1 | T14: 0 | U14: 0.4 | V14: 0 | W14: =V14/D14 -> 0 | X14: =O14-(Q14+R14+T14+U14-V14) -> 0 | AC14: 0 | AD14: =AC14/D14 -> 0 | AG14: 1 | AH14: =AG14/C14 -> 0.012970169 | AI14: =(AG14-AN14)/C14 -> 0.012970169 | AJ14: =AG14-(AK14+AL14+AM14+AN14) -> -0.1 | AK14: 1 | AL14: 0.1 | AM14: 0 | AN14: 0 | AO14: 0 | AP14: 1.207 | AT14: =(O14-AG14)/C14 -> 0.051880674 | AU14: 0.19 | AV14: =(AK14+AL14)/(G14+L14-T14) -> 0.21601208 | AX14: =(AG14-AN14-AM14)/(G14+L14-T14+V14) -> 0.19637462 | AY14: =(AG14-AN14-AM14+AO14)/(G14+L14-T14+AO14) -> 0.19637462 | AZ14: =(AG14-AN14-AM14+AO14)/(G14+L14-T14+AO14-AC14) -> 0.19637462 | BA14: =(AG14-AN14)/Q14 -> 0.24390244 | BB14: =(AG14-AN14)/(Q14+R14) -> 0.2173913 | BC14: =D14 -> 5 | BD14: =BC14-(BE14+BF14+BG14) -> 0 | BE14: =AG14 -> 1 | BF14: 3.2 | BG14: 0.8 | BH14: =BG14/D14 -> 0.16 | BI14: 0.8 | BJ14: =BG14-BI14 -> 0 | BK14: =BJ14/D14 -> 0
